Workbook
Name ENTRY: #REF!
Name INV: #REF!

Sheet Summary
A1: SUMMARY
A3: S. No | B3: Vendor | C3: Style | D3: Balance | E3: Unit | F3: Invoice Date | G3: Invoice No. | H3: Invoice Amount | I3: Bill Status | J3: Sheet Name | K3: gid
A4: =IF(B4="","",COUNTA($B$4:B4)) -> 1 | B4: ='A Kida'!C2 -> AMAN EMBROIDERY | C4: ='A Kida'!C4 -> B/Mat Kida (Chiraag) | D4: ='A Kida'!E5 -> 0 | E4: ='A Kida'!E6 -> PCS | F4: ='A Kida'!C5 | G4: ='A Kida'!C6 | H4: ='A Kida'!E2 | I4: =IF(G4<>"",3,IF(D4=0,2,1)) -> 2 | J4: A Kida | K4: 557832163
A5: =IF(B5="","",COUNTA($B$4:B5)) -> 2 | B5: ='A Ashoka'!A2 -> Aman Ashoka | C5: ='A Ashoka'!C3 -> Ashoka 60x61 | D5: ='A Ashoka'!C5 -> -466 | E5: ='A Ashoka'!B3 -> Pcs | I5: =IF(G5<>"",3,IF(D5=0,2,1)) -> 1 | J5: A Ashoka | K5: 1368002521
A6: =IF(B6="","",COUNTA($B$4:B6)) -> 3 | B6: ='A Ashoka'!A2 -> Aman Ashoka | C6: ='A Ashoka'!D3 -> Ashoka 60x62 | D6: ='A Ashoka'!D5 -> 0 | E6: ='A Ashoka'!B3 -> Pcs | I6: =IF(G6<>"",3,IF(D6=0,2,1)) -> 2 | J6: A Ashoka | K6: 1368002521
A7: =IF(B7="","",COUNTA($B$4:B7)) -> 4 | B7: ='A Ashoka'!A2 -> Aman Ashoka | C7: ='A Ashoka'!E3 -> Ashoka 20x28 | D7: ='A Ashoka'!E5 -> -636 | E7: ='A Ashoka'!B3 -> Pcs | I7: =IF(G7<>"",3,IF(D7=0,2,1)) -> 1 | J7: A Ashoka | K7: 1368002521
A8: =IF(B8="","",COUNTA($B$4:B8)) -> 5 | B8: ='A Ashoka'!A2 -> Aman Ashoka | C8: ='A Ashoka'!F3 -> Ashoka 60x60 | D8: ='A Ashoka'!F5 -> 0 | E8: ='A Ashoka'!B3 -> Pcs | I8: =IF(G8<>"",3,IF(D8=0,2,1)) -> 2 | J8: A Ashoka | K8: 1368002521
A9: =IF(B9="","",COUNTA($B$4:B9)) -> 6 | B9: ='A Ashoka'!A2 -> Aman Ashoka | C9: ='A Ashoka'!G3 -> Ashoka 20x21 | D9: ='A Ashoka'!G5 -> -345 | E9: ='A Ashoka'!B3 -> Pcs | I9: =IF(G9<>"",3,IF(D9=0,2,1)) -> 1 | J9: A Ashoka | K9: 1368002521
A10: =IF(B10="","",COUNTA($B$4:B10)) -> 7 | B10: ='A Ashoka'!A2 -> Aman Ashoka | C10: ='A Ashoka'!H3 -> Ashoka 20x24 | D10: ='A Ashoka'!H5 -> 0 | E10: ='A Ashoka'!B3 -> Pcs | I10: =IF(G10<>"",3,IF(D10=0,2,1)) -> 2 | J10: A Ashoka | K10: 1368002521
A11: =IF(B11="","",COUNTA($B$4:B11)) -> 8 | B11: ='A Ashoka'!A2 -> Aman Ashoka | C11: ='A Ashoka'!I3 -> Ashoka 20x29 | D11: ='A Ashoka'!I5 -> 0 | E11: ='A Ashoka'!B3 -> Pcs | I11: =IF(G11<>"",3,IF(D11=0,2,1)) -> 2 | J11: A Ashoka | K11: 1368002521
A12: =IF(B12="","",COUNTA($B$4:B12)) -> 9 | B12: =CRA!C2 -> CRA CREATIVE PVT LTD | C12: =CRA!C4 -> COTTON PALLA WHITE | D12: =CRA!E5 -> -78 | E12: =CRA!E6 -> PCS | I12: =IF(G12<>"",3,IF(D12=0,2,1)) -> 1 | J12: CRA | K12: 61789952
A13: =IF(B13="","",COUNTA($B$4:B13)) -> 10 | B13: ='T082502'!C2 -> TAURUS HOME | C13: ='T082502'!C4 -> TRS-0825-02 BROWN | D13: ='T082502'!E5 -> 18 | E13: ='T082502'!E6 -> PCS | F13: ='T082502'!C5 -> PART BILLING | G13: ='T082502'!C6 | H13: ='T082502'!E2 | I13: =IF(G13<>"",3,IF(D13=0,2,1)) -> 1 | J13: T082502 | K13: 41232755
A14: =IF(B14="","",COUNTA($B$4:B14)) -> 11 | B14: ='T092531'!C2 -> TAURUS HOME | C14: ='T092531'!C4 -> TRS-0925-31 GREEN | D14: ='T092531'!E5 -> 6 | E14: ='T092531'!E6 -> PCS | F14: ='T092531'!C5 -> PART BILLING | G14: ='T092531'!C6 | H14: ='T092531'!E2 | I14: =IF(G14<>"",3,IF(D14=0,2,1)) -> 1 | J14: T092531 | K14: 1211725013
A15: =IF(B15="","",COUNTA($B$4:B15)) -> 12 | B15: ='A Petal'!C2 -> AMAN EMBROIDERY | C15: ='A Petal'!C4 -> Comferter # Petals | D15: ='A Petal'!E5 -> -212 | E15: ='A Petal'!E6 -> PCS | I15: =IF(G15<>"",3,IF(D15=0,2,1)) -> 1 | J15: A Petal | K15: 898179956
A16: =IF(B16="","",COUNTA($B$4:B16)) -> 13 | B16: ='A Ashoka'!A2 -> Aman Ashoka | C16: ='A Ashoka'!L3 -> Ashoka 60X656 | D16: ='A Ashoka'!L5 -> -108 | E16: ='A Ashoka'!B3 -> Pcs | I16: =IF(G16<>"",3,IF(D16=0,2,1)) -> 1 | J16: A Ashoka | K16: 1368002521
A17: =IF(B17="","",COUNTA($B$4:B17)) -> 14 | B17: ='A ThrowN'!A2 -> Aman Embroidery Throw | C17: ='A ThrowN'!C3 -> 50 x 50 | D17: ='A ThrowN'!D5 -> -5 | E17: ='A ThrowN'!B3 -> SHEET | I17: =IF(G17<>"",3,IF(D17=0,2,1)) -> 1 | J17: A ThrowN | K17: 1218692301
A18: =IF(B18="","",COUNTA($B$4:B18)) -> 15 | B18: ='A ThrowN'!A2 -> Aman Embroidery Throw | C18: ='A ThrowN'!E3 -> 45 x 45 | D18: ='A ThrowN'!F5 -> -0.84 | E18: ='A ThrowN'!B3 -> SHEET | I18: =IF(G18<>"",3,IF(D18=0,2,1)) -> 1 | J18: A ThrowN | K18: 1218692301
A19: =IF(B19="","",COUNTA($B$4:B19)) -> 16 | B19: ='A ThrowN'!A2 -> Aman Embroidery Throw | C19: ='A ThrowN'!G3 -> 130 x 180 | D19: ='A ThrowN'!H5 -> 4.33 | E19: ='A ThrowN'!B3 -> SHEET | I19: =IF(G19<>"",3,IF(D19=0,2,1)) -> 1 | J19: A ThrowN | K19: 1218692301
A20: =IF(B20="","",COUNTA($B$4:B20)) -> 17 | B20: ='A Lucky'!C2 -> AMAN EMBROIDERY | C20: ='A Lucky'!C9 -> A Lucky | D20: ='A Lucky'!E5 -> -1006 | E20: ='A Lucky'!E6 -> PCS | F20: ='A Lucky'!C5 | G20: ='A Lucky'!C6 | H20: ='A Lucky'!E2 | I20: =IF(G20<>"",3,IF(D20=0,2,1)) -> 1 | J20: A Lucky | K20: 587242362
A21: =IF(B21="","",COUNTA($B$4:B21)) -> 18 | B21: ='T1018011'!C2 -> TAURUS HOME | C21: ='T1018011'!C4 -> ACT-1018-011 | D21: ='T1018011'!E5 -> -323 | E21: ='T1018011'!E6 -> PCS | F21: ='T1018011'!C5 -> PART BILLING | G21: ='T1018011'!C6 | H21: ='T1018011'!E2 | I21: =IF(G21<>"",3,IF(D21=0,2,1)) -> 1 | J21: T1018011 | K21: 1149010944
A22: =IF(B22="","",COUNTA($B$4:B22)) -> 19 | B22: ='T042102'!C2 -> TAURUS HOME | C22: ='T042102'!C4 -> CPTR - 0421 - 02 | D22: ='T042102'!E5 -> 0 | E22: ='T042102'!E6 -> PCS | F22: ='T042102'!C5 -> 46154 | G22: ='T042102'!C6 -> MC/26-27/16 | H22: ='T042102'!E2 -> 438900 | I22: =IF(G22<>"",3,IF(D22=0,2,1)) -> 3 | J22: T042102 | K22: 1176506853
A23: =IF(B23="","",COUNTA($B$4:B23)) -> 20 | B23: ='A Ashoka'!A2 -> Aman Ashoka | C23: ='A Ashoka'!M3 -> Ashoka 24X24 | D23: ='A Ashoka'!M5 -> -944 | E23: ='A Ashoka'!B3 -> Pcs | I23: =IF(G23<>"",3,IF(D23=0,2,1)) -> 1 | J23: A Ashoka | K23: 1368002521
A24: =IF(B24="","",COUNTA($B$4:B24)) -> 21 | B24: ='T102404'!C2 -> TAURUS HOME | C24: ='T102404'!C4 -> CPTR-1024-04 | D24: ='T102404'!E5 -> 0 | E24: ='T102404'!E6 -> PCS | F24: ='T102404'!C5 -> 46154 | G24: ='T102404'!C6 -> MC/26-27/17 | H24: ='T102404'!E2 -> 190579 | I24: =IF(G24<>"",3,IF(D24=0,2,1)) -> 3 | J24: T102404 | K24: 86307262
A25: =IF(B25="","",COUNTA($B$4:B25)) -> 22 | B25: ='A Ashoka'!A2 -> Aman Ashoka | C25: ='A Ashoka'!J3 -> Ashoka 20x27 | D25: ='A Ashoka'!J5 -> 215 | E25: ='A Ashoka'!B3 -> Pcs | I25: =IF(G25<>"",3,IF(D25=0,2,1)) -> 1 | J25: A Ashoka | K25: 1368002521
A26: =IF(B26="","",COUNTA($B$4:B26)) -> 23 | B26: ='A Ashoka'!A2 -> Aman Ashoka | C26: ='A Ashoka'!K3 -> Ashoka 20x23 | D26: ='A Ashoka'!K5 -> 0 | E26: ='A Ashoka'!B3 -> Pcs | I26: =IF(G26<>"",3,IF(D26=0,2,1)) -> 2 | J26: A Ashoka | K26: 1368002521
A27: =IF(B27="","",COUNTA($B$4:B27)) -> 24 | B27: ='A Ashoka'!A2 -> Aman Ashoka | C27: ='A Ashoka'!O3 -> LUMAR 14X33 | D27: ='A Ashoka'!O5 -> -332 | E27: ='A Ashoka'!B3 -> Pcs | I27: =IF(G27<>"",3,IF(D27=0,2,1)) -> 1 | J27: A Ashoka | K27: 1368002521
A28: =IF(B28="","",COUNTA($B$4:B28)) -> 25 | B28: ='A Ashoka'!A2 -> Aman Ashoka | C28: ='A Ashoka'!P3 -> Ashoka 20X32 | D28: ='A Ashoka'!P5 -> -626 | E28: ='A Ashoka'!B3 -> Pcs | I28: =IF(G28<>"",3,IF(D28=0,2,1)) -> 1 | J28: A Ashoka | K28: 1368002521
A29: =IF(B29="","",COUNTA($B$4:B29)) -> 26 | B29: ='A Ashoka'!A2 -> Aman Ashoka | C29: ='A Ashoka'!Q3 -> Ashoka LOOP2 | D29: ='A Ashoka'!Q5 -> -300 | E29: ='A Ashoka'!B3 -> Pcs | I29: =IF(G29<>"",3,IF(D29=0,2,1)) -> 1 | J29: A Ashoka | K29: 1368002521
A30: =IF(B30="","",COUNTA($B$4:B30)) -> 27 | B30: ='A Ashoka'!A2 -> Aman Ashoka | C30: ='A Ashoka'!R3 -> Ashoka 24x25 | D30: ='A Ashoka'!R5 -> -320 | E30: ='A Ashoka'!B3 -> Pcs | I30: =IF(G30<>"",3,IF(D30=0,2,1)) -> 1 | J30: A Ashoka | K30: 1368002521
A31: =IF(B31="","",COUNTA($B$4:B31)) -> 28 | B31: ='A Ashoka'!A2 -> Aman Ashoka | C31: ='A Ashoka'!S3 -> Ashoka 20x34 | D31: ='A Ashoka'!S5 -> -308 | E31: ='A Ashoka'!B3 -> Pcs | I31: =IF(G31<>"",3,IF(D31=0,2,1)) -> 1 | J31: A Ashoka | K31: 1368002521
A32: =IF(B32="","",COUNTA($B$4:B32)) -> 29 | B32: ='A Ashoka'!A2 -> Aman Ashoka | C32: ='A Ashoka'!T3 -> Ashoka 20x322 | D32: ='A Ashoka'!T5 -> -300 | E32: ='A Ashoka'!B3 -> Pcs | I32: =IF(G32<>"",3,IF(D32=0,2,1)) -> 1 | J32: A Ashoka | K32: 1368002521
A33: =IF(B33="","",COUNTA($B$4:B33)) -> 30 | B33: ='A Ashoka'!A2 -> Aman Ashoka | C33: ='A Ashoka'!N3 -> LUMAR 14X37 | D33: ='A Ashoka'!N5 -> -267 | E33: ='A Ashoka'!B3 -> Pcs | I33: =IF(G33<>"",3,IF(D33=0,2,1)) -> 1 | J33: A Ashoka | K33: 1368002521
A34: =IF(B34="","",COUNTA($B$4:B34)) -> 31 | B34: =AKIDAN!C2 -> AMAN EMBROIDERY | C34: =AKIDAN!C4 -> B/Mat Kida (Chiraag) NEW | D34: =AKIDAN!E5 -> -240 | E34: =AKIDAN!E6 -> PCS | I34: =IF(G34<>"",3,IF(D34=0,2,1)) -> 1 | J34: AKIDAN | K34: 450036756
A35: =IF(B35="","",COUNTA($B$4:B35)) -> 32 | B35: =AMULTI!C2 -> AMAN EMBROIDERY | C35: =AMULTI!C4 -> B/MAT MULTI LOVE NEXT | D35: =AMULTI!E5 -> 650 | E35: =AMULTI!E6 -> PCS | I35: =IF(G35<>"",3,IF(D35=0,2,1)) -> 1 | J35: AMULTI | K35: 928151764
A36: =IF(B36="","",COUNTA($B$4:B36)) -> 33 | B36: ='T0225'!C2 -> TAURUS HOME | C36: ='T0225'!C4 -> TRS-0225-126 | D36: ='T0225'!E5 -> 0 | E36: ='T0225'!E6 -> PCS | F36: ='T0225'!C5 -> 46183 | G36: ='T0225'!C6 -> MC/26-27/25 | H36: ='T0225'!E2 -> 92529 | I36: =IF(G36<>"",3,IF(D36=0,2,1)) -> 3 | J36: T0225 | K36: 975539521
A37: =IF(B37="","",COUNTA($B$4:B37)) -> 34 | B37: =Adot55!C2 -> AMAN EMBROIDERY | C37: =Adot55!C4 -> DOT DESIGN 55" | D37: =Adot55!E5 -> -31.645833 | E37: =Adot55!E6 -> SHEET | I37: =IF(G37<>"",3,IF(D37=0,2,1)) -> 1 | J37: Adot55 | K37: 1550279639
A38: =IF(B38="","",COUNTA($B$4:B38)) -> 35 | B38: =KCT!C2 -> KRITIKA CREATION | C38: =KCT!C4 -> TREE AARI 60 | D38: =KCT!E5 -> 0 | E38: =KCT!E6 -> PCS | F38: =KCT!C5 -> 46190 | G38: =KCT!C6 -> MC/26-27/31 | H38: =KCT!E2 -> 85000 | I38: =IF(G38<>"",3,IF(D38=0,2,1)) -> 3 | J38: KCT | K38: 1813039516
A39: =IF(B39="","",COUNTA($B$4:B39)) -> 36 | B39: =KCC!C2 -> KRITIKA CREATION | C39: =KCC!C4 -> COUSHION MAHAJAN | D39: =KCC!E5 -> 0 | E39: =KCC!E6 -> PCS | F39: =KCC!C5 -> 46186 | G39: =KCC!C6 -> mc/2026-27/30 | H39: =KCC!E2 -> 77500 | I39: =IF(G39<>"",3,IF(D39=0,2,1)) -> 3 | J39: KCC | K39: 490532876
A40: =IF(B40="","",COUNTA($B$4:B40)) -> 37 | B40: =T101811N!C2 -> TAURUS HOME | C40: =T101811N!C4 -> ACT-1018-011 | D40: =T101811N!E5 -> 326 | E40: =T101811N!E6 -> PCS | I40: =IF(G40<>"",3,IF(D40=0,2,1)) -> 1 | J40: T101811N | K40: 1827899053
A41: =IF(B41="","",COUNTA($B$4:B41)) -> 38 | B41: =ASTRAW!C2 -> AMAN EMBROIDERY | C41: =ASTRAW!C4 -> STRAWBERRY WHITE | D41: =ASTRAW!E5 -> -390 | E41: =ASTRAW!E6 -> PCS | F41: =ASTRAW!C5 | G41: =ASTRAW!C6 | H41: =ASTRAW!E2 | I41: =IF(G41<>"",3,IF(D41=0,2,1)) -> 1 | J41: ASTRAW | K41: 222455884
...

Sheet Report
A1: MALIK CREATION | M1: KPI BOX
A3: S. No | B3: Vendor | C3: Style | D3: Balance | E3: Unit | F3: Invoice Date | G3: Invoice No. | H3: Invoice Amount | I3: Bill Status | J3: Open Sheet | L3: OPEN STYLE | M3: PENDING | N3: NIL | O3: INVOICE
A4: {={SEQUENCE(ROWS(Summary!B4:B430),1),SORT(Summary!B4:K430,Summary!I4:I430,TRUE,Summary!B4:B430,TRUE,Summary!D4:D430,TRUE)}} -> 1 | B4: Aman Ashoka | C4: LUMAR 14X390 | D4: -2500 | E4: Pcs | I4: 1 | J4: A Ashoka | K4: 1368002521 | L4: 🔍 LUMAR 14X390 | M4: =COUNTIF(I:I,1) -> 99 | N4: =COUNTIF(I:I,2) -> 25 | O4: =COUNTIF(I:I,3) -> 21
A5: 2 | B5: Aman Ashoka | C5: Ashoka 24X24 | D5: -944 | E5: Pcs | I5: 1 | J5: A Ashoka | K5: 1368002521 | L5: 🔍 Ashoka 24X24
A6: 3 | B6: Aman Ashoka | C6: LUMAR 14X36 | D6: -808 | E6: Pcs | I6: 1 | J6: A Ashoka | K6: 1368002521 | L6: 🔍 LUMAR 14X36 | M6: D-1476 ORGANZA SUIT | P6: 🔍 D-1476 ORGANZA SUIT
A7: 4 | B7: Aman Ashoka | C7: Ashoka 20x28 | D7: -636 | E7: Pcs | I7: 1 | J7: A Ashoka | K7: 1368002521 | L7: 🔍 Ashoka 20x28
A8: 5 | B8: Aman Ashoka | C8: Ashoka 20X32 | D8: -626 | E8: Pcs | I8: 1 | J8: A Ashoka | K8: 1368002521 | L8: 🔍 Ashoka 20X32
A9: 6 | B9: Aman Ashoka | C9: Ashoka 60x61 | D9: -466 | E9: Pcs | I9: 1 | J9: A Ashoka | K9: 1368002521 | L9: 🔍 Ashoka 60x61
A10: 7 | B10: Aman Ashoka | C10: LUMAR 02315 | D10: -403 | E10: Pcs | I10: 1 | J10: A Ashoka | K10: 1368002521 | L10: 🔍 LUMAR 02315
A11: 8 | B11: Aman Ashoka | C11: Lumar 14x42 | D11: -400 | E11: Pcs | I11: 1 | J11: A Ashoka | K11: 1368002521 | L11: 🔍 Lumar 14x42
A12: 9 | B12: Aman Ashoka | C12: Ashoka 20x21 | D12: -345 | E12: Pcs | I12: 1 | J12: A Ashoka | K12: 1368002521 | L12: 🔍 Ashoka 20x21
A13: 10 | B13: Aman Ashoka | C13: LUMAR 14X33 | D13: -332 | E13: Pcs | I13: 1 | J13: A Ashoka | K13: 1368002521 | L13: 🔍 LUMAR 14X33
A14: 11 | B14: Aman Ashoka | C14: Ashoka 24x25 | D14: -320 | E14: Pcs | I14: 1 | J14: A Ashoka | K14: 1368002521 | L14: 🔍 Ashoka 24x25
A15: 12 | B15: Aman Ashoka | C15: Ashoka 20x34 | D15: -308 | E15: Pcs | I15: 1 | J15: A Ashoka | K15: 1368002521 | L15: 🔍 Ashoka 20x34
A16: 13 | B16: Aman Ashoka | C16: Ashoka LOOP2 | D16: -300 | E16: Pcs | I16: 1 | J16: A Ashoka | K16: 1368002521 | L16: 🔍 Ashoka LOOP2
A17: 14 | B17: Aman Ashoka | C17: Ashoka 20x322 | D17: -300 | E17: Pcs | I17: 1 | J17: A Ashoka | K17: 1368002521 | L17: 🔍 Ashoka 20x322
A18: 15 | B18: Aman Ashoka | C18: Ashoka 20X25 | D18: -300 | E18: Pcs | I18: 1 | J18: A Ashoka | K18: 1368002521 | L18: 🔍 Ashoka 20X25
... A78: 75 | B78: AMAN MEHTA | C78: B/MAT GRAY 40X60 | D78: -88 | E78: Pcs | I78: 1 | J78: AMEHTA | K78: 2129093570 | L78: 🔍 B/MAT GRAY 40X60
A79: 76 | B79: ART & DESIGN | C79: 1552 SAREE | D79: -53 | E79: PCS | I79: 1 | J79: A1552SAREE | K79: 69255005 | L79: 🔍 1552 SAREE | M79: 52 | N79: 44
A80: 77 | B80: ART & DESIGN | C80: D-1462 ORGANZA DUPATTA | D80: 14 | E80: MTRS | I80: 1 | J80: D1462DUP | K80: 1396879749 | L80: 🔍 D-1462 ORGANZA DUPATTA
A81: 78 | B81: ART & DESIGN | C81: D-1481 STK MUL SUIT | D81: 50 | E81: PCS | I81: 1 | J81: A1481STK | K81: 204775831 | L81: 🔍 D-1481 STK MUL SUIT
A82: 79 | B82: ART & DESIGN | C82: D-1476 MUL SUIT | D82: 50 | E82: PCS | I82: 1 | J82: A1476-2 | K82: 1463558953 | L82: 🔍 D-1476 MUL SUIT
A83: 80 | B83: ART & DESIGN | C83: D-1415 MUL SUIT | D83: 50 | E83: PCS | I83: 1 | J83: A1415-2 | K83: 162365241 | L83: 🔍 D-1415 MUL SUIT
A84: 81 | B84: ART & DESIGN | C84: D-1481 MUL SUIT | D84: 59 | E84: PCS | I84: 1 | J84: A1481-2 | K84: 869372670 | L84: 🔍 D-1481 MUL SUIT
A85: 82 | B85: ART & DESIGN | C85: D-1442 VISCOSE ORGANZA RED | D85: 61 | E85: PCS | I85: 1 | J85: D1442 | K85: 1105355549 | L85: 🔍 D-1442 VISCOSE ORGANZA RED
A86: 83 | B86: ART & DESIGN | C86: ART CREPE BLOUSE | D86: 62 | E86: MTRS | I86: 1 | J86: ARTCREPE | K86: 2064921695 | L86: 🔍 ART CREPE BLOUSE
A87: 84 | B87: CRA CREATIVE | C87: SANTA | D87: -392 | E87: PCS | I87: 1 | J87: CRASANTA | K87: 1309455546 | L87: 🔍 SANTA
A88: 85 | B88: CRA CREATIVE PVT LTD | C88: STOCKING | D88: -2456 | E88: PCS | I88: 1 | J88: Cra Stocking | K88: 1749420872 | L88: 🔍 STOCKING
A89: 86 | B89: CRA CREATIVE PVT LTD | C89: WHITE PILLOW | D89: -765 | E89: PCS | I89: 1 | J89: Cra Pillow | K89: 205219033 | L89: 🔍 WHITE PILLOW
A90: 87 | B90: CRA CREATIVE PVT LTD | C90: NOEL ROD | D90: -745 | E90: PCS | I90: 1 | J90: Cra Noel | K90: 1443304496 | L90: 🔍 NOEL ROD
A91: 88 | B91: CRA CREATIVE PVT LTD | C91: WHITE BED SHEET 108X114 | D91: -105 | E91: PCS | I91: 1 | J91: CRA | K91: 61789952 | L91: 🔍 WHITE BED SHEET 108X114
... A93: 90 | B93: CRA CREATIVE PVT LTD | C93: WHITE BED SHEET 96X114 | D93: -65 | E93: PCS | I93: 1 | J93: CRA | K93: 61789952 | L93: 🔍 WHITE BED SHEET 96X114
A94: 91 | B94: CRA CREATIVE PVT LTD | C94: WHITE BED SHEET 114x78 | D94: -40 | E94: PCS | I94: 1 | J94: CRA | K94: 61789952 | L94: 🔍 WHITE BED SHEET 114x78 | M94: PCS FOR INVOICE
A95: 92 | B95: CRA CREATIVE PVT LTD | C95: CANDY | D95: -40 | E95: PCS | I95: 1 | J95: Cra Candy | K95: 392176783 | L95: 🔍 CANDY | M95: 43
A96: 93 | B96: CRA CREATIVE PVT LTD | C96: WHITE BED SHEET 30X57 | D96: -22 | E96: PCS | I96: 1 | J96: CRA | K96: 61789952 | L96: 🔍 WHITE BED SHEET 30X57 | M96: 53
A97: 94 | B97: CRA CREATIVE PVT LTD | C97: TREE | D97: -20 | E97: PCS | I97: 1 | J97: Cra Tree | K97: 340881030 | L97: 🔍 TREE | M97: 38
A98: 95 | B98: CRA CREATIVE PVT LTD | C98: HALLY LEAF | D98: -5 | E98: PCS | I98: 1 | J98: Cra Hally | K98: 1443281762 | L98: 🔍 HALLY LEAF | M98: 25
A99: 96 | B99: TAURUS HOME | C99: ACT-1018-011 | D99: -323 | E99: PCS | F99: PART BILLING | I99: 1 | J99: T1018011 | K99: 1149010944 | L99: 🔍 ACT-1018-011 | M99: 8
A100: 97 | B100: TAURUS HOME | C100: TRS-0925-31 GREEN | D100: 6 | E100: PCS | F100: PART BILLING | I100: 1 | J100: T092531 | K100: 1211725013 | L100: 🔍 TRS-0925-31 GREEN | M100: 30
A101: 98 | B101: TAURUS HOME | C101: TRS-0825-02 BROWN | D101: 18 | E101: PCS | F101: PART BILLING | I101: 1 | J101: T082502 | K101: 41232755 | L101: 🔍 TRS-0825-02 BROWN
...

Sheet A1481-2
A1: ⬅ BACK TO REPORT
A2: Vendor Name | C2: ART & DESIGN | D2: Invoice Amount
A3: Place | C3: NOIDA | D3: In | E3: =SUM(D9:D100) -> 59
A4: Style / Po No.: | C4: D-1481 MUL SUIT | D4: Out | E4: =SUM(E9:E100) -> 0
A5: Invoice Date | D5: Bal Qty | E5: {=LOOKUP(9,1/(F:F<>""),F:F)} -> 59
A6: Invoice Number | D6: Unit | E6: PCS
A8: Date | B8: Challan No. | C8: Size | D8: Inward Qty | E8: Outward Qty | F8: Balance
A9: 46234 | B9: JB-0634/26-27 | C9: =C4 -> D-1481 MUL SUIT | D9: 59 | F9: =D9-E9 -> 59
F10: =IF(OR(D10<>"",E10<>""),F9+D10-E10,"")
F11: =IF(OR(D11<>"",E11<>""),F10+D11-E11,"")
F12: =IF(OR(D12<>"",E12<>""),F11+D12-E12,"")
F13: =IF(OR(D13<>"",E13<>""),F12+D13-E13,"")
F14: =IF(OR(D14<>"",E14<>""),F13+D14-E14,"")
F15: =IF(OR(D15<>"",E15<>""),F14+D15-E15,"")
F16: =IF(OR(D16<>"",E16<>""),F15+D16-E16,"")
F17: =IF(OR(D17<>"",E17<>""),F16+D17-E17,"")
F18: =IF(OR(D18<>"",E18<>""),F17+D18-E18,"")
F19: =IF(OR(D19<>"",E19<>""),F18+D19-E19,"")
F20: =IF(OR(D20<>"",E20<>""),F19+D20-E20,"")
F21: =IF(OR(D21<>"",E21<>""),F20+D21-E21,"")
... F52: =IF(OR(D52<>"",E52<>""),F51+D52-E52,"")

Sheet A1476-2
A1: ⬅ BACK TO REPORT
A2: Vendor Name | C2: ART & DESIGN | D2: Invoice Amount
A3: Place | C3: NOIDA | D3: In | E3: =SUM(D9:D100) -> 50
A4: Style / Po No.: | C4: D-1476 MUL SUIT | D4: Out | E4: =SUM(E9:E100) -> 0
A5: Invoice Date | D5: Bal Qty | E5: {=LOOKUP(9,1/(F:F<>""),F:F)} -> 50
A6: Invoice Number | D6: Unit | E6: PCS
A8: Date | B8: Challan No. | C8: Size | D8: Inward Qty | E8: Outward Qty | F8: Balance
A9: 46234 | B9: JB-0634/26-27 | C9: =C4 -> D-1476 MUL SUIT | D9: 50 | F9: =D9-E9 -> 50
F10: =IF(OR(D10<>"",E10<>""),F9+D10-E10,"")
F11: =IF(OR(D11<>"",E11<>""),F10+D11-E11,"")
F12: =IF(OR(D12<>"",E12<>""),F11+D12-E12,"")
F13: =IF(OR(D13<>"",E13<>""),F12+D13-E13,"")
F14: =IF(OR(D14<>"",E14<>""),F13+D14-E14,"")
F15: =IF(OR(D15<>"",E15<>""),F14+D15-E15,"")
F16: =IF(OR(D16<>"",E16<>""),F15+D16-E16,"")
F17: =IF(OR(D17<>"",E17<>""),F16+D17-E17,"")
F18: =IF(OR(D18<>"",E18<>""),F17+D18-E18,"")
F19: =IF(OR(D19<>"",E19<>""),F18+D19-E19,"")
F20: =IF(OR(D20<>"",E20<>""),F19+D20-E20,"")
F21: =IF(OR(D21<>"",E21<>""),F20+D21-E21,"")
... F52: =IF(OR(D52<>"",E52<>""),F51+D52-E52,"")

Sheet A1415-2
A1: ⬅ BACK TO REPORT
A2: Vendor Name | C2: ART & DESIGN | D2: Invoice Amount
A3: Place | C3: NOIDA | D3: In | E3: =SUM(D9:D100) -> 50
A4: Style / Po No.: | C4: D-1415 MUL SUIT | D4: Out | E4: =SUM(E9:E100) -> 0
A5: Invoice Date | D5: Bal Qty | E5: {=LOOKUP(9,1/(F:F<>""),F:F)} -> 50
A6: Invoice Number | D6: Unit | E6: PCS
A8: Date | B8: Challan No. | C8: Size | D8: Inward Qty | E8: Outward Qty | F8: Balance
A9: 46234 | B9: JB-0634/26-27 | C9: =C4 -> D-1415 MUL SUIT | D9: 50 | F9: =D9-E9 -> 50
F10: =IF(OR(D10<>"",E10<>""),F9+D10-E10,"")
F11: =IF(OR(D11<>"",E11<>""),F10+D11-E11,"")
F12: =IF(OR(D12<>"",E12<>""),F11+D12-E12,"")
F13: =IF(OR(D13<>"",E13<>""),F12+D13-E13,"")
F14: =IF(OR(D14<>"",E14<>""),F13+D14-E14,"")
F15: =IF(OR(D15<>"",E15<>""),F14+D15-E15,"")
F16: =IF(OR(D16<>"",E16<>""),F15+D16-E16,"")
F17: =IF(OR(D17<>"",E17<>""),F16+D17-E17,"")
F18: =IF(OR(D18<>"",E18<>""),F17+D18-E18,"")
F19: =IF(OR(D19<>"",E19<>""),F18+D19-E19,"")
F20: =IF(OR(D20<>"",E20<>""),F19+D20-E20,"")
F21: =IF(OR(D21<>"",E21<>""),F20+D21-E21,"")
... F52: =IF(OR(D52<>"",E52<>""),F51+D52-E52,"")

Sheet A1558
A1: ⬅ BACK TO REPORT
A2: Vendor Name | C2: ART & DESIGN | D2: Invoice Amount
A3: Place | C3: NOIDA | D3: In | E3: =SUM(D9:D100) -> 43
A4: Style / Po No.: | C4: 1558 | D4: Out | E4: =SUM(E9:E100) -> 43
A5: Invoice Date | D5: Bal Qty | E5: {=LOOKUP(9,1/(F:F<>""),F:F)} -> 0
A6: Invoice Number | D6: Unit | E6: PCS
A8: Date | B8: Challan No. | C8: Size | D8: Inward Qty | E8: Outward Qty | F8: Balance
A9: 46234 | B9: WITHOUT CHALLAN | C9: =C4 -> 1558 | D9: 43 | F9: =D9-E9 -> 43
A10: 46234 | B10: 1889 | E10: 43 | F10: =IF(OR(D10<>"",E10<>""),F9+D10-E10,"") -> 0
F11: =IF(OR(D11<>"",E11<>""),F10+D11-E11,"")
F12: =IF(OR(D12<>"",E12<>""),F11+D12-E12,"")
F13: =IF(OR(D13<>"",E13<>""),F12+D13-E13,"")
F14: =IF(OR(D14<>"",E14<>""),F13+D14-E14,"")
F15: =IF(OR(D15<>"",E15<>""),F14+D15-E15,"")
F16: =IF(OR(D16<>"",E16<>""),F15+D16-E16,"")
F17: =IF(OR(D17<>"",E17<>""),F16+D17-E17,"")
F18: =IF(OR(D18<>"",E18<>""),F17+D18-E18,"")
F19: =IF(OR(D19<>"",E19<>""),F18+D19-E19,"")
F20: =IF(OR(D20<>"",E20<>""),F19+D20-E20,"")
F21: =IF(OR(D21<>"",E21<>""),F20+D21-E21,"")
F22: =IF(OR(D22<>"",E22<>""),F21+D22-E22,"")
... F52: =IF(OR(D52<>"",E52<>""),F51+D52-E52,"")

Sheet A1552SAREE
A1: ⬅ BACK TO REPORT
A2: Vendor Name | C2: ART & DESIGN | D2: Invoice Amount
A3: Place | C3: NOIDA | D3: In | E3: =SUM(D9:D100) -> 0
A4: Style / Po No.: | C4: 1552 SAREE | D4: Out | E4: =SUM(E9:E100) -> 53
A5: Invoice Date | D5: Bal Qty | E5: {=LOOKUP(9,1/(F:F<>""),F:F)} -> -53
A6: Invoice Number | D6: Unit | E6: PCS
A8: Date | B8: Challan No. | C8: Size | D8: Inward Qty | E8: Outward Qty | F8: Balance
A9: 46228 | B9: 1886 | C9: =C4 -> 1552 SAREE | E9: 53 | F9: =D9-E9 -> -53
F10: =IF(OR(D10<>"",E10<>""),F9+D10-E10,"")
F11: =IF(OR(D11<>"",E11<>""),F10+D11-E11,"")
F12: =IF(OR(D12<>"",E12<>""),F11+D12-E12,"")
F13: =IF(OR(D13<>"",E13<>""),F12+D13-E13,"")
F14: =IF(OR(D14<>"",E14<>""),F13+D14-E14,"")
F15: =IF(OR(D15<>"",E15<>""),F14+D15-E15,"")
F16: =IF(OR(D16<>"",E16<>""),F15+D16-E16,"")
F17: =IF(OR(D17<>"",E17<>""),F16+D17-E17,"")
F18: =IF(OR(D18<>"",E18<>""),F17+D18-E18,"")
F19: =IF(OR(D19<>"",E19<>""),F18+D19-E19,"")
F20: =IF(OR(D20<>"",E20<>""),F19+D20-E20,"")
F21: =IF(OR(D21<>"",E21<>""),F20+D21-E21,"")
... F52: =IF(OR(D52<>"",E52<>""),F51+D52-E52,"")

Sheet A1481STK
A1: ⬅ BACK TO REPORT
A2: Vendor Name | C2: ART & DESIGN | D2: Invoice Amount
A3: Place | C3: NOIDA | D3: In | E3: =SUM(D9:D100) -> 50
A4: Style / Po No.: | C4: D-1481 STK MUL SUIT | D4: Out | E4: =SUM(E9:E100) -> 0
A5: Invoice Date | D5: Bal Qty | E5: {=LOOKUP(9,1/(F:F<>""),F:F)} -> 50
A6: Invoice Number | D6: Unit | E6: PCS
A8: Date | B8: Challan No. | C8: Size | D8: Inward Qty | E8: Outward Qty | F8: Balance
A9: 46228 | B9: JB-0606/26-27 | C9: =C4 -> D-1481 STK MUL SUIT | D9: 50 | F9: =D9-E9 -> 50
F10: =IF(OR(D10<>"",E10<>""),F9+D10-E10,"")
F11: =IF(OR(D11<>"",E11<>""),F10+D11-E11,"")
F12: =IF(OR(D12<>"",E12<>""),F11+D12-E12,"")
F13: =IF(OR(D13<>"",E13<>""),F12+D13-E13,"")
F14: =IF(OR(D14<>"",E14<>""),F13+D14-E14,"")
F15: =IF(OR(D15<>"",E15<>""),F14+D15-E15,"")
F16: =IF(OR(D16<>"",E16<>""),F15+D16-E16,"")
F17: =IF(OR(D17<>"",E17<>""),F16+D17-E17,"")
F18: =IF(OR(D18<>"",E18<>""),F17+D18-E18,"")
F19: =IF(OR(D19<>"",E19<>""),F18+D19-E19,"")
F20: =IF(OR(D20<>"",E20<>""),F19+D20-E20,"")
F21: =IF(OR(D21<>"",E21<>""),F20+D21-E21,"")
... F52: =IF(OR(D52<>"",E52<>""),F51+D52-E52,"")

Sheet AMANSLAB
A1: ⬅ BACK TO REPORT
A2: Vendor Name | C2: AMAN EMBROIDERY | D2: Invoice Amount
A3: Place | C3: PANIPAT | D3: In | E3: =SUM(D9:D100) -> 0
A4: Style / Po No.: | C4: SLAB | D4: Out | E4: =SUM(E9:E100) -> 605
A5: Invoice Date | D5: Bal Qty | E5: {=LOOKUP(9,1/(F:F<>""),F:F)} -> -605
A6: Invoice Number | D6: Unit | E6: PCS
A8: Date | B8: Challan No. | C8: Size | D8: Inward Qty | E8: Outward Qty | F8: Balance
A9: 46225 | B9: 79 | C9: =C4 -> SLAB | E9: 7 | F9: =D9-E9 -> -7 | H9: PLUS 1 O/S
A10: 46229 | B10: 80 | E10: 598 | F10: =IF(OR(D10<>"",E10<>""),F9+D10-E10,"") -> -605
F11: =IF(OR(D11<>"",E11<>""),F10+D11-E11,"")
F12: =IF(OR(D12<>"",E12<>""),F11+D12-E12,"")
F13: =IF(OR(D13<>"",E13<>""),F12+D13-E13,"")
F14: =IF(OR(D14<>"",E14<>""),F13+D14-E14,"")
F15: =IF(OR(D15<>"",E15<>""),F14+D15-E15,"")
F16: =IF(OR(D16<>"",E16<>""),F15+D16-E16,"")
F17: =IF(OR(D17<>"",E17<>""),F16+D17-E17,"")
F18: =IF(OR(D18<>"",E18<>""),F17+D18-E18,"")
F19: =IF(OR(D19<>"",E19<>""),F18+D19-E19,"")
F20: =IF(OR(D20<>"",E20<>""),F19+D20-E20,"")
F21: =IF(OR(D21<>"",E21<>""),F20+D21-E21,"")
F22: =IF(OR(D22<>"",E22<>""),F21+D22-E22,"")
... F52: =IF(OR(D52<>"",E52<>""),F51+D52-E52,"")

Sheet A1415O
A1: ⬅ BACK TO REPORT
A2: Vendor Name | C2: ART & DESIGN | D2: Invoice Amount
A3: Place | C3: NOIDA | D3: In | E3: =SUM(D9:D100) -> 37
A4: Style / Po No.: | C4: D-1415 ORGANZA SUIT | D4: Out | E4: =SUM(E9:E100) -> 37
A5: Invoice Date | D5: Bal Qty | E5: {=LOOKUP(9,1/(F:F<>""),F:F)} -> 0
A6: Invoice Number | D6: Unit | E6: PCS
A8: Date | B8: Challan No. | C8: Size | D8: Inward Qty | E8: Outward Qty | F8: Balance
A9: 46228 | B9: JB-0606/26-27 | C9: =C4 -> D-1415 ORGANZA SUIT | D9: 37 | F9: =D9-E9 -> 37
A10: 46241 | B10: 1891 | E10: 37 | F10: =IF(OR(D10<>"",E10<>""),F9+D10-E10,"") -> 0
F11: =IF(OR(D11<>"",E11<>""),F10+D11-E11,"")
F12: =IF(OR(D12<>"",E12<>""),F11+D12-E12,"")
F13: =IF(OR(D13<>"",E13<>""),F12+D13-E13,"")
F14: =IF(OR(D14<>"",E14<>""),F13+D14-E14,"")
F15: =IF(OR(D15<>"",E15<>""),F14+D15-E15,"")
F16: =IF(OR(D16<>"",E16<>""),F15+D16-E16,"")
F17: =IF(OR(D17<>"",E17<>""),F16+D17-E17,"")
F18: =IF(OR(D18<>"",E18<>""),F17+D18-E18,"")
F19: =IF(OR(D19<>"",E19<>""),F18+D19-E19,"")
F20: =IF(OR(D20<>"",E20<>""),F19+D20-E20,"")
F21: =IF(OR(D21<>"",E21<>""),F20+D21-E21,"")
F22: =IF(OR(D22<>"",E22<>""),F21+D22-E22,"")
... F52: =IF(OR(D52<>"",E52<>""),F51+D52-E52,"")

Sheet A1476O
A1: ⬅ BACK TO REPORT
A2: Vendor Name | C2: ART & DESIGN | D2: Invoice Amount
A3: Place | C3: NOIDA | D3: In | E3: =SUM(D9:D100) -> 37
A4: Style / Po No.: | C4: D-1476 ORGANZA SUIT | D4: Out | E4: =SUM(E9:E100) -> 37
A5: Invoice Date | D5: Bal Qty | E5: {=LOOKUP(9,1/(F:F<>""),F:F)} -> 0
A6: Invoice Number | D6: Unit | E6: PCS
A8: Date | B8: Challan No. | C8: Size | D8: Inward Qty | E8: Outward Qty | F8: Balance
A9: 46228 | B9: JB-0606/26-27 | C9: =C4 -> D-1476 ORGANZA SUIT | D9: 37 | F9: =D9-E9 -> 37
A10: 46239 | B10: 1890 | E10: 2 | F10: =IF(OR(D10<>"",E10<>""),F9+D10-E10,"") -> 35
A11: 46244 | B11: 1894 | E11: 35 | F11: =IF(OR(D11<>"",E11<>""),F10+D11-E11,"") -> 0
F12: =IF(OR(D12<>"",E12<>""),F11+D12-E12,"")
F13: =IF(OR(D13<>"",E13<>""),F12+D13-E13,"")
F14: =IF(OR(D14<>"",E14<>""),F13+D14-E14,"")
F15: =IF(OR(D15<>"",E15<>""),F14+D15-E15,"")
F16: =IF(OR(D16<>"",E16<>""),F15+D16-E16,"")
F17: =IF(OR(D17<>"",E17<>""),F16+D17-E17,"")
F18: =IF(OR(D18<>"",E18<>""),F17+D18-E18,"")
F19: =IF(OR(D19<>"",E19<>""),F18+D19-E19,"")
F20: =IF(OR(D20<>"",E20<>""),F19+D20-E20,"")
F21: =IF(OR(D21<>"",E21<>""),F20+D21-E21,"")
F22: =IF(OR(D22<>"",E22<>""),F21+D22-E22,"")
F23: =IF(OR(D23<>"",E23<>""),F22+D23-E23,"")
... F52: =IF(OR(D52<>"",E52<>""),F51+D52-E52,"")

Sheet A1415STK
A1: ⬅ BACK TO REPORT
A2: Vendor Name | C2: ART & DESIGN | D2: Invoice Amount
A3: Place | C3: NOIDA | D3: In | E3: =SUM(D9:D100) -> 50
A4: Style / Po No.: | C4: D-1415 STK MUL SUIT | D4: Out | E4: =SUM(E9:E100) -> 50
A5: Invoice Date | D5: Bal Qty | E5: {=LOOKUP(9,1/(F:F<>""),F:F)} -> 0
A6: Invoice Number | D6: Unit | E6: PCS
A8: Date | B8: Challan No. | C8: Size | D8: Inward Qty | E8: Outward Qty | F8: Balance
A9: 46228 | B9: JB-0606/26-27 | C9: =C4 -> D-1415 STK MUL SUIT | D9: 50 | F9: =D9-E9 -> 50
A10: 46241 | B10: 1891 | C10: 1893 | E10: 50 | F10: =IF(OR(D10<>"",E10<>""),F9+D10-E10,"") -> 0
F11: =IF(OR(D11<>"",E11<>""),F10+D11-E11,"")
F12: =IF(OR(D12<>"",E12<>""),F11+D12-E12,"")
F13: =IF(OR(D13<>"",E13<>""),F12+D13-E13,"")
F14: =IF(OR(D14<>"",E14<>""),F13+D14-E14,"")
F15: =IF(OR(D15<>"",E15<>""),F14+D15-E15,"")
F16: =IF(OR(D16<>"",E16<>""),F15+D16-E16,"")
F17: =IF(OR(D17<>"",E17<>""),F16+D17-E17,"")
F18: =IF(OR(D18<>"",E18<>""),F17+D18-E18,"")
F19: =IF(OR(D19<>"",E19<>""),F18+D19-E19,"")
F20: =IF(OR(D20<>"",E20<>""),F19+D20-E20,"")
F21: =IF(OR(D21<>"",E21<>""),F20+D21-E21,"")
F22: =IF(OR(D22<>"",E22<>""),F21+D22-E22,"")
... F52: =IF(OR(D52<>"",E52<>""),F51+D52-E52,"")

Sheet D1442
A1: ⬅ BACK TO REPORT
A2: Vendor Name | C2: ART & DESIGN | D2: Invoice Amount
A3: Place | C3: NOIDA | D3: In | E3: =SUM(D9:D100) -> 61
A4: Style / Po No.: | C4: D-1442 VISCOSE ORGANZA RED | D4: Out | E4: =SUM(E9:E100) -> 0
A5: Invoice Date | D5: Bal Qty | E5: {=LOOKUP(9,1/(F:F<>""),F:F)} -> 61
A6: Invoice Number | D6: Unit | E6: PCS
A8: Date | B8: Challan No. | C8: Size | D8: Inward Qty | E8: Outward Qty | F8: Balance
A9: 46224 | B9: JB-0578/26-27 | C9: =C4 -> D-1442 VISCOSE ORGANZA RED | D9: 47 | F9: =D9-E9 -> 47
A10: 46228 | B10: JB-0606/26-27 | C10: 1442 VISCOSE ORGANZA | D10: 14 | F10: =IF(OR(D10<>"",E10<>""),F9+D10-E10,"") -> 61
F11: =IF(OR(D11<>"",E11<>""),F10+D11-E11,"")
F12: =IF(OR(D12<>"",E12<>""),F11+D12-E12,"")
F13: =IF(OR(D13<>"",E13<>""),F12+D13-E13,"")
F14: =IF(OR(D14<>"",E14<>""),F13+D14-E14,"")
F15: =IF(OR(D15<>"",E15<>""),F14+D15-E15,"")
F16: =IF(OR(D16<>"",E16<>""),F15+D16-E16,"")
F17: =IF(OR(D17<>"",E17<>""),F16+D17-E17,"")
F18: =IF(OR(D18<>"",E18<>""),F17+D18-E18,"")
F19: =IF(OR(D19<>"",E19<>""),F18+D19-E19,"")
F20: =IF(OR(D20<>"",E20<>""),F19+D20-E20,"")
F21: =IF(OR(D21<>"",E21<>""),F20+D21-E21,"")
F22: =IF(OR(D22<>"",E22<>""),F21+D22-E22,"")
... F52: =IF(OR(D52<>"",E52<>""),F51+D52-E52,"")

Sheet ARTCREPE
A1: ⬅ BACK TO REPORT
A2: Vendor Name | C2: ART & DESIGN | D2: Invoice Amount
A3: Place | C3: NOIDA | D3: In | E3: =SUM(D9:D100) -> 62
A4: Style / Po No.: | C4: ART CREPE BLOUSE | D4: Out | E4: =SUM(E9:E100) -> 0
A5: Invoice Date | D5: Bal Qty | E5: {=LOOKUP(9,1/(F:F<>""),F:F)} -> 62
A6: Invoice Number | D6: Unit | E6: MTRS
A8: Date | B8: Challan No. | C8: Size | D8: Inward Qty | E8: Outward Qty | F8: Balance
A9: 46224 | B9: JB-0578/26-27 | C9: =C4 -> ART CREPE BLOUSE | D9: 46 | F9: =D9-E9 -> 46
A10: 46228 | B10: JB-0606/26-27 | C10: ART CREPE RED | D10: 16 | F10: =IF(OR(D10<>"",E10<>""),F9+D10-E10,"") -> 62
F11: =IF(OR(D11<>"",E11<>""),F10+D11-E11,"")
F12: =IF(OR(D12<>"",E12<>""),F11+D12-E12,"")
F13: =IF(OR(D13<>"",E13<>""),F12+D13-E13,"")
F14: =IF(OR(D14<>"",E14<>""),F13+D14-E14,"")
F15: =IF(OR(D15<>"",E15<>""),F14+D15-E15,"")
F16: =IF(OR(D16<>"",E16<>""),F15+D16-E16,"")
F17: =IF(OR(D17<>"",E17<>""),F16+D17-E17,"")
F18: =IF(OR(D18<>"",E18<>""),F17+D18-E18,"")
F19: =IF(OR(D19<>"",E19<>""),F18+D19-E19,"")
F20: =IF(OR(D20<>"",E20<>""),F19+D20-E20,"")
F21: =IF(OR(D21<>"",E21<>""),F20+D21-E21,"")
F22: =IF(OR(D22<>"",E22<>""),F21+D22-E22,"")
... F52: =IF(OR(D52<>"",E52<>""),F51+D52-E52,"")

Sheet AT221N
A1: ⬅ BACK TO REPORT | K1: =SUMIF(J9:J52,J1,K9:K52) -> 0
A2: Vendor Name | C2: ART & DESIGN | D2: Invoice Amount
A3: Place | C3: NOIDA | D3: In | E3: =SUM(D9:D100) -> 101.9
A4: Style / Po No.: | C4: T-221 JAMWAR PRINT MUL | D4: Out | E4: =SUM(E9:E100) -> 101.9
A5: Invoice Date | D5: Bal Qty | E5: {=LOOKUP(9,1/(F:F<>""),F:F)} -> 0
A6: Invoice Number | D6: Unit | E6: MTRS
H7: WORK ORDER NO. | K7: =SUM(K9:K102) -> 0
A8: Date | B8: Challan No. | C8: Size | D8: Inward Qty | E8: Outward Qty | F8: Balance | H8: Date | I8: Challan No. | J8: Item | K8: Qty | L8: Unit | M8: For
A9: 46224 | B9: JB-0578/26-27 | C9: =C4 -> T-221 JAMWAR PRINT MUL | D9: 43.55 | F9: =D9-E9 -> 43.55
A10: 46224 | D10: 58.35 | F10: =IF(OR(D10<>"",E10<>""),F9+D10-E10,"") -> 101.9
A11: 46232 | B11: 1888 | E11: 101.9 | F11: =IF(OR(D11<>"",E11<>""),F10+D11-E11,"") -> 0
F12: =IF(OR(D12<>"",E12<>""),F11+D12-E12,"")
F13: =IF(OR(D13<>"",E13<>""),F12+D13-E13,"")
F14: =IF(OR(D14<>"",E14<>""),F13+D14-E14,"")
F15: =IF(OR(D15<>"",E15<>""),F14+D15-E15,"")
F16: =IF(OR(D16<>"",E16<>""),F15+D16-E16,"")
F17: =IF(OR(D17<>"",E17<>""),F16+D17-E17,"")
F18: =IF(OR(D18<>"",E18<>""),F17+D18-E18,"")
F19: =IF(OR(D19<>"",E19<>""),F18+D19-E19,"")
F20: =IF(OR(D20<>"",E20<>""),F19+D20-E20,"")
F21: =IF(OR(D21<>"",E21<>""),F20+D21-E21,"")
F22: =IF(OR(D22<>"",E22<>""),F21+D22-E22,"")
F23: =IF(OR(D23<>"",E23<>""),F22+D23-E23,"")
... F52: =IF(OR(D52<>"",E52<>""),F51+D52-E52,"")

Sheet AT214
A1: ⬅ BACK TO REPORT | K1: =SUMIF(J9:J52,J1,K9:K52) -> 0
A2: Vendor Name | C2: ART & DESIGN | D2: Invoice Amount
A3: Place | C3: NOIDA | D3: In | E3: =SUM(D9:D100) -> 191.3
A4: Style / Po No.: | C4: T-214 GOLD TISSUE | D4: Out | E4: =SUM(E9:E100) -> 191.3
A5: Invoice Date | D5: Bal Qty | E5: {=LOOKUP(9,1/(F:F<>""),F:F)} -> 0
A6: Invoice Number | D6: Unit | E6: MTRS
H7: WORK ORDER NO. | K7: =SUM(K9:K102) -> 0
A8: Date | B8: Challan No. | C8: Size | D8: Inward Qty | E8: Outward Qty | F8: Balance | H8: Date | I8: Challan No. | J8: Item | K8: Qty | L8: Unit | M8: For
A9: 46224 | B9: JB-0578/26-27 | C9: =C4 -> T-214 GOLD TISSUE | D9: 191.3 | F9: =D9-E9 -> 191.3
A10: 46234 | B10: 1889 | E10: 191.3 | F10: =IF(OR(D10<>"",E10<>""),F9+D10-E10,"") -> 0
F11: =IF(OR(D11<>"",E11<>""),F10+D11-E11,"")
F12: =IF(OR(D12<>"",E12<>""),F11+D12-E12,"")
F13: =IF(OR(D13<>"",E13<>""),F12+D13-E13,"")
F14: =IF(OR(D14<>"",E14<>""),F13+D14-E14,"")
F15: =IF(OR(D15<>"",E15<>""),F14+D15-E15,"")
F16: =IF(OR(D16<>"",E16<>""),F15+D16-E16,"")
F17: =IF(OR(D17<>"",E17<>""),F16+D17-E17,"")
F18: =IF(OR(D18<>"",E18<>""),F17+D18-E18,"")
F19: =IF(OR(D19<>"",E19<>""),F18+D19-E19,"")
F20: =IF(OR(D20<>"",E20<>""),F19+D20-E20,"")
F21: =IF(OR(D21<>"",E21<>""),F20+D21-E21,"")
F22: =IF(OR(D22<>"",E22<>""),F21+D22-E22,"")
... F52: =IF(OR(D52<>"",E52<>""),F51+D52-E52,"")

Sheet ABEDD
A1: ⬅ BACK TO REPORT | H1: ⬅ BACK TO REPORT | O1: ⬅ BACK TO REPORT | V1: ⬅ BACK TO REPORT
A2: Vendor Name | C2: AMAN EMBROIDERY | D2: Invoice Amount | H2: Vendor Name | J2: AMAN EMBROIDERY | K2: Invoice Amount | O2: Vendor Name | Q2: AMAN EMBROIDERY | R2: Invoice Amount | V2: Vendor Name | X2: AMAN EMBROIDERY | Y2: Invoice Amount
A3: Place | C3: PANIPAT | D3: In | E3: =SUM(D9:D100) -> 0 | H3: Place | J3: PANIPAT | K3: In | L3: =SUM(K9:K100) -> 0 | O3: Place | Q3: PANIPAT | R3: In | S3: =SUM(R9:R100) -> 0 | V3: Place | X3: PANIPAT | Y3: In | Z3: =SUM(Y9:Y100) -> 0
A4: Style / Po No.: | C4: BED SHEET DIAMOND | D4: Out | E4: =SUM(E9:E100) -> 265 | H4: Style / Po No.: | J4: PILLOW DIAMOND FOME | K4: Out | L4: =SUM(L9:L100) -> 270 | O4: Style / Po No.: | Q4: PILLOW DIAMOND | R4: Out | S4: =SUM(S9:S100) -> 577 | V4: Style / Po No.: | X4: DIAMOND PILLO VELVATE | Y4: Out | Z4: =SUM(Z9:Z100) -> 257
A5: Invoice Date | D5: Bal Qty | E5: {=LOOKUP(9,1/(F:F<>""),F:F)} -> -265 | H5: Invoice Date | K5: Bal Qty | L5: {=LOOKUP(9,1/(M:M<>""),M:M)} -> -270 | O5: Invoice Date | R5: Bal Qty | S5: {=LOOKUP(9,1/(T:T<>""),T:T)} -> -577 | V5: Invoice Date | Y5: Bal Qty | Z5: {=LOOKUP(9,1/(AA:AA<>""),AA:AA)} -> -257
A6: Invoice Number | D6: Unit | E6: PCS | H6: Invoice Number | K6: Unit | L6: PCS | O6: Invoice Number | R6: Unit | S6: PCS | V6: Invoice Number | Y6: Unit | Z6: PCS
A8: Date | B8: Challan No. | C8: Size | D8: Inward Qty | E8: Outward Qty | F8: Balance | H8: Date | I8: Challan No. | J8: Size | K8: Inward Qty | L8: Outward Qty | M8: Balance | O8: Date | P8: Challan No. | Q8: Size | R8: Inward Qty | S8: Outward Qty | T8: Balance | V8: Date | W8: Challan No. | X8: Size | Y8: Inward Qty | Z8: Outward Qty | AA8: Balance
A9: 46177 | B9: 45 | C9: =C4 -> BED SHEET DIAMOND | E9: 32 | F9: =D9-E9 -> -32 | H9: 46184 | I9: 49 | J9: =J4 -> PILLOW DIAMOND FOME | L9: 270 | M9: =K9-L9 -> -270 | O9: 46185 | P9: 50 | Q9: =Q4 -> PILLOW DIAMOND | S9: 273 | T9: =R9-S9 -> -273 | V9: 46570 | W9: 72 | X9: =X4 -> DIAMOND PILLO VELVATE | Z9: 144 | AA9: =Y9-Z9 -> -144
A10: 46178 | B10: 46 | E10: 97 | F10: =IF(OR(D10<>"",E10<>""),F9+D10-E10,"") -> -129 | M10: =IF(OR(K10<>"",L10<>""),M9+K10-L10,"") | O10: 46202 | P10: 67 | S10: 304 | T10: =IF(OR(R10<>"",S10<>""),T9+R10-S10,"") -> -577 | V10: 46206 | W10: 73 | Z10: 113 | AA10: =IF(OR(Y10<>"",Z10<>""),AA9+Y10-Z10,"") -> -257
A11: 46181 | B11: 47 | E11: 19 | F11: =IF(OR(D11<>"",E11<>""),F10+D11-E11,"") -> -148 | M11: =IF(OR(K11<>"",L11<>""),M10+K11-L11,"") | T11: =IF(OR(R11<>"",S11<>""),T10+R11-S11,"") | AA11: =IF(OR(Y11<>"",Z11<>""),AA10+Y11-Z11,"")
A12: 46195 | B12: 60 | E12: 93 | F12: =IF(OR(D12<>"",E12<>""),F11+D12-E12,"") -> -241 | M12: =IF(OR(K12<>"",L12<>""),M11+K12-L12,"") | T12: =IF(OR(R12<>"",S12<>""),T11+R12-S12,"") | AA12: =IF(OR(Y12<>"",Z12<>""),AA11+Y12-Z12,"")
A13: 46205 | B13: 72 | E13: 24 | F13: =IF(OR(D13<>"",E13<>""),F12+D13-E13,"") -> -265 | M13: =IF(OR(K13<>"",L13<>""),M12+K13-L13,"") | T13: =IF(OR(R13<>"",S13<>""),T12+R13-S13,"") | AA13: =IF(OR(Y13<>"",Z13<>""),AA12+Y13-Z13,"")
F14: =IF(OR(D14<>"",E14<>""),F13+D14-E14,"") | M14: =IF(OR(K14<>"",L14<>""),M13+K14-L14,"") | T14: =IF(OR(R14<>"",S14<>""),T13+R14-S14,"") | AA14: =IF(OR(Y14<>"",Z14<>""),AA13+Y14-Z14,"")
F15: =IF(OR(D15<>"",E15<>""),F14+D15-E15,"") | M15: =IF(OR(K15<>"",L15<>""),M14+K15-L15,"") | T15: =IF(OR(R15<>"",S15<>""),T14+R15-S15,"") | AA15: =IF(OR(Y15<>"",Z15<>""),AA14+Y15-Z15,"")
F16: =IF(OR(D16<>"",E16<>""),F15+D16-E16,"") | M16: =IF(OR(K16<>"",L16<>""),M15+K16-L16,"") | T16: =IF(OR(R16<>"",S16<>""),T15+R16-S16,"") | AA16: =IF(OR(Y16<>"",Z16<>""),AA15+Y16-Z16,"")
F17: =IF(OR(D17<>"",E17<>""),F16+D17-E17,"") | M17: =IF(OR(K17<>"",L17<>""),M16+K17-L17,"") | T17: =IF(OR(R17<>"",S17<>""),T16+R17-S17,"") | AA17: =IF(OR(Y17<>"",Z17<>""),AA16+Y17-Z17,"")
F18: =IF(OR(D18<>"",E18<>""),F17+D18-E18,"") | M18: =IF(OR(K18<>"",L18<>""),M17+K18-L18,"") | T18: =IF(OR(R18<>"",S18<>""),T17+R18-S18,"") | AA18: =IF(OR(Y18<>"",Z18<>""),AA17+Y18-Z18,"")
F19: =IF(OR(D19<>"",E19<>""),F18+D19-E19,"") | M19: =IF(OR(K19<>"",L19<>""),M18+K19-L19,"") | T19: =IF(OR(R19<>"",S19<>""),T18+R19-S19,"") | AA19: =IF(OR(Y19<>"",Z19<>""),AA18+Y19-Z19,"")
F20: =IF(OR(D20<>"",E20<>""),F19+D20-E20,"") | M20: =IF(OR(K20<>"",L20<>""),M19+K20-L20,"") | T20: =IF(OR(R20<>"",S20<>""),T19+R20-S20,"") | AA20: =IF(OR(Y20<>"",Z20<>""),AA19+Y20-Z20,"")
F21: =IF(OR(D21<>"",E21<>""),F20+D21-E21,"") | M21: =IF(OR(K21<>"",L21<>""),M20+K21-L21,"") | T21: =IF(OR(R21<>"",S21<>""),T20+R21-S21,"") | AA21: =IF(OR(Y21<>"",Z21<>""),AA20+Y21-Z21,"")
F22: =IF(OR(D22<>"",E22<>""),F21+D22-E22,"") | M22: =IF(OR(K22<>"",L22<>""),M21+K22-L22,"") | T22: =IF(OR(R22<>"",S22<>""),T21+R22-S22,"") | AA22: =IF(OR(Y22<>"",Z22<>""),AA21+Y22-Z22,"")
F23: =IF(OR(D23<>"",E23<>""),F22+D23-E23,"") | M23: =IF(OR(K23<>"",L23<>""),M22+K23-L23,"") | T23: =IF(OR(R23<>"",S23<>""),T22+R23-S23,"") | AA23: =IF(OR(Y23<>"",Z23<>""),AA22+Y23-Z23,"")
F24: =IF(OR(D24<>"",E24<>""),F23+D24-E24,"") | M24: =IF(OR(K24<>"",L24<>""),M23+K24-L24,"") | T24: =IF(OR(R24<>"",S24<>""),T23+R24-S24,"") | AA24: =IF(OR(Y24<>"",Z24<>""),AA23+Y24-Z24,"")
F25: =IF(OR(D25<>"",E25<>""),F24+D25-E25,"") | M25: =IF(OR(K25<>"",L25<>""),M24+K25-L25,"") | T25: =IF(OR(R25<>"",S25<>""),T24+R25-S25,"") | AA25: =IF(OR(Y25<>"",Z25<>""),AA24+Y25-Z25,"")
... F52: =IF(OR(D52<>"",E52<>""),F51+D52-E52,"") | M52: =IF(OR(K52<>"",L52<>""),M51+K52-L52,"") | T52: =IF(OR(R52<>"",S52<>""),T51+R52-S52,"") | AA52: =IF(OR(Y52<>"",Z52<>""),AA51+Y52-Z52,"")

Sheet AMEHTA
A1: ⬅ BACK TO REPORT | Z1: Mtrs | AA1: Pcs | AB1: Mtrs
A2: AMAN MEHTA | C2: =C103 -> 133 | D2: =D103 -> 227 | E2: =E103 -> 153 | F2: =F103 -> 130 | G2: =G103 -> 183 | H2: =H103 -> 112 | I2: =I103 -> 92 | J2: =J103 -> 88 | ... AB2: =AB103 -> 0
A3: B/MAT | B3: Pcs | C3: B/MAT BEIGE 60X120 | D3: B/MAT WHITE 50X80 | E3: B/MAT WHITE CANTOOR | F3: B/MAT BEIGE CANTOOR | G3: B/MAT BEIGE 50X80 | H3: B/MAT GRAY CANTOOR | I3: B/MAT BEIGE 40X60 | J3: B/MAT GRAY 40X60 | K3: B/MAT GRAY 60X120 | L3: B/MAT WHITE 40X60 | M3: B/MAT WHITE 60X120 | N3: B/MAT GRAY 50X80
A4: Date | B4: Challan No.
C5: =C4-C2 -> -133 | D5: =D4-D2 -> -227 | E5: =E4-E2 -> -153 | F5: =F4-F2 -> -130 | G5: =G4-G2 -> -183 | H5: =H4-H2 -> -112 | I5: =I4-I2 -> -92 | J5: =J4-J2 -> -88 | ... AB5: =AB4-AB2 -> 0 | AD5: TOTAL
A6: 46199 | B6: 63 | C6: 5 | AD6: =sum(C6:X6) -> 5
A7: 46203 | B7: 69 | C7: 128 | D7: 170 | E7: 148 | G7: 150 | AD7: =sum(C7:X7) -> 596
A8: 46204 | B8: 70 | H8: 2 | AD8: =sum(C8:X8) -> 2
A9: 46205 | B9: 72 | D9: 57 | F9: 125 | G9: 3 | I9: 92 | J9: 88 | K9: 12 | L9: 90 | M9: 101 | AD9: =sum(C9:X9) -> 568
A10: 46209 | B10: 74 | H10: 50 | K10: 90 | AD10: =sum(C10:X10) -> 140
A11: 46214 | B11: 75 | H11: 59 | AD11: =sum(C11:X11) -> 59
A12: 46217 | B12: 77 | G12: 30 | AD12: =sum(C12:X12) -> 30
A13: 46220 | B13: 78 | M13: 46 | N13: 50 | AD13: =sum(C13:X13) -> 96
A14: 46225 | B14: 79 | N14: 20 | AD14: =sum(C14:X14) -> 20
A15: 46229 | B15: 80 | N15: 30 | AD15: =sum(C15:X15) -> 30
A16: 46233 | B16: 81 | N16: 66 | AD16: =sum(C16:X16) -> 66
A17: 46242 | B17: 82 | E17: 5 | F17: 5 | H17: 1 | K17: 2 | AD17: =sum(C17:X17) -> 13
AD18: =sum(C18:X18) -> 0
AD19: =sum(C19:X19) -> 0
AD20: =sum(C20:X20) -> 0
AD21: =sum(C21:X21) -> 0
AD22: =sum(C22:X22) -> 0
AD23: =sum(C23:X23) -> 0
AD24: =sum(C24:X24) -> 0
AD25: =sum(C25:X25) -> 0
AD26: =sum(C26:X26) -> 0
AD27: =sum(C27:X27) -> 0
AD28: =sum(C28:X28) -> 0
AD29: =sum(C29:X29) -> 0
... AD102: =sum(C102:X102) -> 0
B103: TOTAL | C103: =SUM(C6:C102) -> 133 | D103: =SUM(D6:D102) -> 227 | E103: =SUM(E6:E102) -> 153 | F103: =SUM(F6:F102) -> 130 | G103: =SUM(G6:G102) -> 183 | H103: =SUM(H6:H102) -> 112 | I103: =SUM(I6:I102) -> 92 | J103: =SUM(J6:J102) -> 88 | ... AB103: =SUM(AB6:AB102) -> 0 | AD103: =SUM(AD6:AD102) -> 1625
B104: Balance

Sheet A1552NEW
A1: ⬅ BACK TO REPORT | H1: ⬅ BACK TO REPORT | O1: ⬅ BACK TO REPORT
A2: Vendor Name | C2: ART & DESIGN | D2: Invoice Amount | E2: 38479 | H2: Vendor Name | J2: ART & DESIGN | K2: Invoice Amount | L2: 28044 | O2: Vendor Name | Q2: ART & DESIGN | R2: Invoice Amount
A3: Place | C3: NOIDA | D3: In | E3: =SUM(D9:D100) -> 59 | H3: Place | J3: NOIDA | K3: In | L3: =SUM(K9:K100) -> 43 | O3: Place | Q3: NOIDA | R3: In | S3: =SUM(R9:R100) -> 30
A4: Style / Po No.: | C4: D-1552 ORGANZA SUIT | D4: Out | E4: =SUM(E9:E100) -> 59 | H4: Style / Po No.: | J4: D-1552 ORGANZA SUIT | K4: Out | L4: =SUM(L9:L100) -> 43 | O4: Style / Po No.: | Q4: D-1552 ORGANZA SUIT | R4: Out | S4: =SUM(S9:S100) -> 30
A5: Invoice Date | C5: 46197 | D5: Bal Qty | E5: {=LOOKUP(9,1/(F:F<>""),F:F)} -> 0 | H5: Invoice Date | J5: 46197 | K5: Bal Qty | L5: {=LOOKUP(9,1/(M:M<>""),M:M)} -> 0 | O5: Invoice Date | R5: Bal Qty | S5: {=LOOKUP(9,1/(T:T<>""),T:T)} -> 0
A6: Invoice Number | C6: MC/26-27/34 | D6: Unit | E6: PCS | H6: Invoice Number | J6: MC/26-27/33 | K6: Unit | L6: PCS | O6: Invoice Number | R6: Unit | S6: PCS
A8: Date | B8: Challan No. | C8: Size | D8: Inward Qty | E8: Outward Qty | F8: Balance | H8: Date | I8: Challan No. | J8: Size | K8: Inward Qty | L8: Outward Qty | M8: Balance | O8: Date | P8: Challan No. | Q8: Size | R8: Inward Qty | S8: Outward Qty | T8: Balance
A9: 46175 | B9: JB-0301/26-27 | C9: =C4 -> D-1552 ORGANZA SUIT | D9: 59 | F9: =D9-E9 -> 59 | H9: 46185 | I9: JB-0355/26-27 | K9: 43 | M9: =K9-L9 -> 43 | O9: 46185 | P9: JB-0355/26-27 | R9: 30 | T9: =R9-S9 -> 30
A10: 46195 | B10: 1874 | E10: 59 | F10: =IF(OR(D10<>"",E10<>""),F9+D10-E10,"") -> 0 | H10: 46198 | I10: 1875 | J10: 2 PCS EXTRA SENT TO CUSTOMER | L10: 43 | M10: =IF(OR(K10<>"",L10<>""),M9+K10-L10,"") -> 0 | O10: 46571 | P10: 1878 | S10: 30 | T10: =IF(OR(R10<>"",S10<>""),T9+R10-S10,"") -> 0
F11: =IF(OR(D11<>"",E11<>""),F10+D11-E11,"") | M11: =IF(OR(K11<>"",L11<>""),M10+K11-L11,"") | T11: =IF(OR(R11<>"",S11<>""),T10+R11-S11,"")
F12: =IF(OR(D12<>"",E12<>""),F11+D12-E12,"") | M12: =IF(OR(K12<>"",L12<>""),M11+K12-L12,"") | T12: =IF(OR(R12<>"",S12<>""),T11+R12-S12,"")
F13: =IF(OR(D13<>"",E13<>""),F12+D13-E13,"") | M13: =IF(OR(K13<>"",L13<>""),M12+K13-L13,"") | T13: =IF(OR(R13<>"",S13<>""),T12+R13-S13,"")
F14: =IF(OR(D14<>"",E14<>""),F13+D14-E14,"") | M14: =IF(OR(K14<>"",L14<>""),M13+K14-L14,"") | T14: =IF(OR(R14<>"",S14<>""),T13+R14-S14,"")
F15: =IF(OR(D15<>"",E15<>""),F14+D15-E15,"") | M15: =IF(OR(K15<>"",L15<>""),M14+K15-L15,"") | T15: =IF(OR(R15<>"",S15<>""),T14+R15-S15,"")
F16: =IF(OR(D16<>"",E16<>""),F15+D16-E16,"") | M16: =IF(OR(K16<>"",L16<>""),M15+K16-L16,"") | T16: =IF(OR(R16<>"",S16<>""),T15+R16-S16,"")
F17: =IF(OR(D17<>"",E17<>""),F16+D17-E17,"") | M17: =IF(OR(K17<>"",L17<>""),M16+K17-L17,"") | T17: =IF(OR(R17<>"",S17<>""),T16+R17-S17,"")
F18: =IF(OR(D18<>"",E18<>""),F17+D18-E18,"") | M18: =IF(OR(K18<>"",L18<>""),M17+K18-L18,"") | T18: =IF(OR(R18<>"",S18<>""),T17+R18-S18,"")
F19: =IF(OR(D19<>"",E19<>""),F18+D19-E19,"") | M19: =IF(OR(K19<>"",L19<>""),M18+K19-L19,"") | T19: =IF(OR(R19<>"",S19<>""),T18+R19-S19,"")
F20: =IF(OR(D20<>"",E20<>""),F19+D20-E20,"") | M20: =IF(OR(K20<>"",L20<>""),M19+K20-L20,"") | T20: =IF(OR(R20<>"",S20<>""),T19+R20-S20,"")
F21: =IF(OR(D21<>"",E21<>""),F20+D21-E21,"") | M21: =IF(OR(K21<>"",L21<>""),M20+K21-L21,"") | T21: =IF(OR(R21<>"",S21<>""),T20+R21-S21,"")
F22: =IF(OR(D22<>"",E22<>""),F21+D22-E22,"") | M22: =IF(OR(K22<>"",L22<>""),M21+K22-L22,"") | T22: =IF(OR(R22<>"",S22<>""),T21+R22-S22,"")
... F52: =IF(OR(D52<>"",E52<>""),F51+D52-E52,"") | M52: =IF(OR(K52<>"",L52<>""),M51+K52-L52,"") | T52: =IF(OR(R52<>"",S52<>""),T51+R52-S52,"")

Sheet 1174SAREENEW
A1: ⬅ BACK TO REPORT | K1: =SUMIF(J9:J52,J1,K9:K52) -> 0
A2: Vendor Name | C2: ART & DESIGN | D2: Invoice Amount
A3: Place | C3: NOIDA | D3: In | E3: =SUM(D9:D100) -> 36
A4: Style / Po No.: | C4: D-1174 SAREE | D4: Out | E4: =SUM(E9:E100) -> 36
A5: Invoice Date | D5: Bal Qty | E5: {=LOOKUP(9,1/(F:F<>""),F:F)} -> 0
A6: Invoice Number | D6: Unit | E6: PCS
H7: WORK ORDER NO. | K7: =SUM(K9:K102) -> 0
A8: Date | B8: Challan No. | C8: Size | D8: Inward Qty | E8: Outward Qty | F8: Balance | H8: Date | I8: Challan No. | J8: Item | K8: Qty | L8: Unit | M8: For
A9: 46203 | B9: JB-0464/26-27 | C9: =C4 -> D-1174 SAREE | D9: 18 | F9: =D9-E9 -> 18
A10: 46579 | B10: 1880 | C10: SAREE 10 | E10: 10 | F10: =IF(OR(D10<>"",E10<>""),F9+D10-E10,"") -> 8
A11: 46214 | B11: 1880 | C11: BLOUSE 18 | E11: 18 | F11: =IF(OR(D11<>"",E11<>""),F10+D11-E11,"") -> -10
A12: 46579 | B12: 1881 | C12: 1174 SAREE | E12: 8 | F12: =IF(OR(D12<>"",E12<>""),F11+D12-E12,"") -> -18
C13: BLOUSE SET ADJUSTMENT | D13: 18 | F13: =IF(OR(D13<>"",E13<>""),F12+D13-E13,"") -> 0
F14: =IF(OR(D14<>"",E14<>""),F13+D14-E14,"")
F15: =IF(OR(D15<>"",E15<>""),F14+D15-E15,"")
F16: =IF(OR(D16<>"",E16<>""),F15+D16-E16,"")
F17: =IF(OR(D17<>"",E17<>""),F16+D17-E17,"")
F18: =IF(OR(D18<>"",E18<>""),F17+D18-E18,"")
F19: =IF(OR(D19<>"",E19<>""),F18+D19-E19,"")
F20: =IF(OR(D20<>"",E20<>""),F19+D20-E20,"")
F21: =IF(OR(D21<>"",E21<>""),F20+D21-E21,"")
F22: =IF(OR(D22<>"",E22<>""),F21+D22-E22,"")
F23: =IF(OR(D23<>"",E23<>""),F22+D23-E23,"")
F24: =IF(OR(D24<>"",E24<>""),F23+D24-E24,"")
F25: =IF(OR(D25<>"",E25<>""),F24+D25-E25,"")
... F52: =IF(OR(D52<>"",E52<>""),F51+D52-E52,"")

Sheet 1501SAREE
A1: ⬅ BACK TO REPORT | H1: ⬅ BACK TO REPORT
A2: Vendor Name | C2: ART & DESIGN | D2: Invoice Amount | E2: 29603 | H2: Vendor Name | J2: ART & DESIGN | K2: Invoice Amount | L2: 2611
A3: Place | C3: NOIDA | D3: In | E3: =SUM(D9:D100) -> 22 | H3: Place | J3: NOIDA | K3: In | L3: =SUM(K9:K100) -> 17
A4: Style / Po No.: | C4: D-1501 TISSUE SAREE | D4: Out | E4: =SUM(E9:E100) -> 22 | H4: Style / Po No.: | J4: TISSUE BLOUSE | K4: Out | L4: =SUM(L9:L100) -> 17
A5: Invoice Date | C5: 46224 | D5: Bal Qty | E5: {=LOOKUP(9,1/(F:F<>""),F:F)} -> 0 | H5: Invoice Date | J5: 46224 | K5: Bal Qty | L5: {=LOOKUP(9,1/(M:M<>""),M:M)} -> 0
A6: Invoice Number | C6: 40 | D6: Unit | E6: PCS | H6: Invoice Number | J6: 40 | K6: Unit | L6: PCS
A8: Date | B8: Challan No. | C8: Size | D8: Inward Qty | E8: Outward Qty | F8: Balance | H8: Date | I8: Challan No. | J8: Size | K8: Inward Qty | L8: Outward Qty | M8: Balance
A9: 46211 | B9: JB-0512/26-27 | C9: =C4 -> D-1501 TISSUE SAREE | D9: 22 | F9: =D9-E9 -> 22 | H9: 46211 | I9: JB-0512/26-27 | J9: =J4 -> TISSUE BLOUSE | K9: 17 | M9: =K9-L9 -> 17
A10: 46224 | B10: 1884 | E10: 22 | F10: =IF(OR(D10<>"",E10<>""),F9+D10-E10,"") -> 0 | H10: 46224 | I10: 1884 | L10: 17 | M10: =IF(OR(K10<>"",L10<>""),M9+K10-L10,"") -> 0
F11: =IF(OR(D11<>"",E11<>""),F10+D11-E11,"") | M11: =IF(OR(K11<>"",L11<>""),M10+K11-L11,"")
F12: =IF(OR(D12<>"",E12<>""),F11+D12-E12,"") | M12: =IF(OR(K12<>"",L12<>""),M11+K12-L12,"")
F13: =IF(OR(D13<>"",E13<>""),F12+D13-E13,"") | M13: =IF(OR(K13<>"",L13<>""),M12+K13-L13,"")
F14: =IF(OR(D14<>"",E14<>""),F13+D14-E14,"") | M14: =IF(OR(K14<>"",L14<>""),M13+K14-L14,"")
F15: =IF(OR(D15<>"",E15<>""),F14+D15-E15,"") | M15: =IF(OR(K15<>"",L15<>""),M14+K15-L15,"")
F16: =IF(OR(D16<>"",E16<>""),F15+D16-E16,"") | M16: =IF(OR(K16<>"",L16<>""),M15+K16-L16,"")
F17: =IF(OR(D17<>"",E17<>""),F16+D17-E17,"") | M17: =IF(OR(K17<>"",L17<>""),M16+K17-L17,"")
F18: =IF(OR(D18<>"",E18<>""),F17+D18-E18,"") | M18: =IF(OR(K18<>"",L18<>""),M17+K18-L18,"")
F19: =IF(OR(D19<>"",E19<>""),F18+D19-E19,"") | M19: =IF(OR(K19<>"",L19<>""),M18+K19-L19,"")
F20: =IF(OR(D20<>"",E20<>""),F19+D20-E20,"") | M20: =IF(OR(K20<>"",L20<>""),M19+K20-L20,"")
F21: =IF(OR(D21<>"",E21<>""),F20+D21-E21,"") | M21: =IF(OR(K21<>"",L21<>""),M20+K21-L21,"")
F22: =IF(OR(D22<>"",E22<>""),F21+D22-E22,"") | M22: =IF(OR(K22<>"",L22<>""),M21+K22-L22,"")
... F52: =IF(OR(D52<>"",E52<>""),F51+D52-E52,"") | M52: =IF(OR(K52<>"",L52<>""),M51+K52-L52,"")

Sheet T191
A1: ⬅ BACK TO REPORT | H1: ⬅ BACK TO REPORT
A2: Vendor Name | C2: ART & DESIGN | D2: Invoice Amount | H2: Vendor Name | J2: ART & DESIGN | K2: Invoice Amount
A3: Place | C3: NOIDA | D3: In | E3: =SUM(D9:D100) -> 300 | H3: Place | J3: NOIDA | K3: In | L3: =SUM(K9:K100) -> 104
A4: Style / Po No.: | C4: T-191 MUL THAN | D4: Out | E4: =SUM(E9:E100) -> 300 | H4: Style / Po No.: | J4: T-191 MUL DUPATTA | K4: Out | L4: =SUM(L9:L100) -> 104
A5: Invoice Date | D5: Bal Qty | E5: {=LOOKUP(9,1/(F:F<>""),F:F)} -> 0 | H5: Invoice Date | K5: Bal Qty | L5: {=LOOKUP(9,1/(M:M<>""),M:M)} -> 0
A6: Invoice Number | D6: Unit | E6: MTRS | H6: Invoice Number | K6: Unit | L6: MTRS
A8: Date | B8: Challan No. | C8: Size | D8: Inward Qty | E8: Outward Qty | F8: Balance | H8: Date | I8: Challan No. | J8: Size | K8: Inward Qty | L8: Outward Qty | M8: Balance
A9: 46211 | B9: JB-0512/26-27 | C9: =C4 -> T-191 MUL THAN | D9: 240 | F9: =D9-E9 -> 240 | H9: 46211 | I9: JB-0512/26-27 | J9: =J4 -> T-191 MUL DUPATTA | K9: 104 | M9: =K9-L9 -> 104
A10: 46211 | B10: JB-0512/26-27 | C10: =C5 | D10: 60 | F10: =IF(OR(D10<>"",E10<>""),F9+D10-E10,"") -> 300 | H10: 46221 | I10: 1883 | L10: 104 | M10: =IF(OR(K10<>"",L10<>""),M9+K10-L10,"") -> 0
A11: 46221 | B11: 1883 | E11: 240.25 | F11: =IF(OR(D11<>"",E11<>""),F10+D11-E11,"") -> 59.75 | M11: =IF(OR(K11<>"",L11<>""),M10+K11-L11,"")
A12: 46224 | B12: 1884 | E12: 59.75 | F12: =IF(OR(D12<>"",E12<>""),F11+D12-E12,"") -> 0 | M12: =IF(OR(K12<>"",L12<>""),M11+K12-L12,"")
F13: =IF(OR(D13<>"",E13<>""),F12+D13-E13,"") | M13: =IF(OR(K13<>"",L13<>""),M12+K13-L13,"")
F14: =IF(OR(D14<>"",E14<>""),F13+D14-E14,"") | M14: =IF(OR(K14<>"",L14<>""),M13+K14-L14,"")
F15: =IF(OR(D15<>"",E15<>""),F14+D15-E15,"") | M15: =IF(OR(K15<>"",L15<>""),M14+K15-L15,"")
F16: =IF(OR(D16<>"",E16<>""),F15+D16-E16,"") | M16: =IF(OR(K16<>"",L16<>""),M15+K16-L16,"")
F17: =IF(OR(D17<>"",E17<>""),F16+D17-E17,"") | M17: =IF(OR(K17<>"",L17<>""),M16+K17-L17,"")
F18: =IF(OR(D18<>"",E18<>""),F17+D18-E18,"") | M18: =IF(OR(K18<>"",L18<>""),M17+K18-L18,"")
F19: =IF(OR(D19<>"",E19<>""),F18+D19-E19,"") | M19: =IF(OR(K19<>"",L19<>""),M18+K19-L19,"")
F20: =IF(OR(D20<>"",E20<>""),F19+D20-E20,"") | M20: =IF(OR(K20<>"",L20<>""),M19+K20-L20,"")
F21: =IF(OR(D21<>"",E21<>""),F20+D21-E21,"") | M21: =IF(OR(K21<>"",L21<>""),M20+K21-L21,"")
F22: =IF(OR(D22<>"",E22<>""),F21+D22-E22,"") | M22: =IF(OR(K22<>"",L22<>""),M21+K22-L22,"")
F23: =IF(OR(D23<>"",E23<>""),F22+D23-E23,"") | M23: =IF(OR(K23<>"",L23<>""),M22+K23-L23,"")
F24: =IF(OR(D24<>"",E24<>""),F23+D24-E24,"") | M24: =IF(OR(K24<>"",L24<>""),M23+K24-L24,"")
... F52: =IF(OR(D52<>"",E52<>""),F51+D52-E52,"") | M52: =IF(OR(K52<>"",L52<>""),M51+K52-L52,"")

Sheet A Ashoka
A1: ⬅ BACK TO REPORT | Z1: Mtrs | AA1: Pcs | AB1: Mtrs
A2: Aman Ashoka | C2: =C103 -> 676 | D2: =D103 -> 210 | E2: =E103 -> 846 | F2: =F103 -> 210 | G2: =G103 -> 555 | H2: =H103 -> 210 | I2: =I103 -> 210 | J2: =J103 -> 295 | ... AB2: =AB103 -> 136.5
A3: Ashoka | B3: Pcs | C3: Ashoka 60x61 | D3: Ashoka 60x62 | E3: Ashoka 20x28 | F3: Ashoka 60x60 | G3: Ashoka 20x21 | H3: Ashoka 20x24 | I3: Ashoka 20x29 | J3: Ashoka 20x27 | K3: Ashoka 20x23 | L3: Ashoka 60X656 | M3: Ashoka 24X24 | N3: LUMAR 14X37 | O3: LUMAR 14X33 | P3: Ashoka 20X32 | Q3: Ashoka LOOP2 | R3: Ashoka 24x25 | S3: Ashoka 20x34 | T3: Ashoka 20x322 | U3: LUMAR 02315 | V3: LUMAR 14X36 | W3: LUMAR 14X390 | X3: Ashoka 58x58 | Y3: Ashoka 20X25 | Z3: Sheet 21x60 | AA3: Lumar 14x42 | AB3: Sheet 60x21
A4: Date | B4: Challan No. | C4: 210 | D4: 210 | E4: 210 | F4: 210 | G4: 210 | H4: 210 | I4: 210 | J4: 510 | K4: 210 | L4: 510 | M4: 510
A5: 9 | C5: =C4-C2 -> -466 | D5: =D4-D2 -> 0 | E5: =E4-E2 -> -636 | F5: =F4-F2 -> 0 | G5: =G4-G2 -> -345 | H5: =H4-H2 -> 0 | I5: =I4-I2 -> 0 | J5: =J4-J2 -> 215 | ... AB5: =AB4-AB2 -> -136.5 | AD5: TOTAL
A6: 46087 | B6: 1703 | K6: 30 | AD6: =sum(C6:AB6) -> 30
A7: 46089 | B7: 1707 | G7: 30 | AD7: =sum(C7:AB7) -> 30
A8: 46090 | B8: 1709 | C8: 1 | D8: 1 | E8: 30 | F8: 1 | AD8: =sum(C8:AB8) -> 33
A9: 46091 | B9: 1710 | H9: 30 | AD9: =sum(C9:AB9) -> 30
A10: 46092 | B10: 1711 | E10: 167 | G10: 162 | H10: 118 | I10: 2 | K10: 163 | AD10: =sum(C10:AB10) -> 612
A11: 46094 | B11: 1714 | C11: 1 | AD11: =sum(C11:AB11) -> 1
A12: 46094 | B12: 1715 | E12: 13 | G12: 18 | H12: 62 | K12: 17 | AD12: =sum(C12:AB12) -> 110
A13: 46095 | B13: 1716 | I13: 208 | AD13: =sum(C13:AB13) -> 208
A14: 46098 | B14: 1719 | D14: 210 | F14: 2 | AD14: =sum(C14:AB14) -> 212
A15: EXTRA | D15: -1 | F15: -2 | AD15: =sum(C15:AB15) -> -3
A16: 46100 | B16: 1721 | F16: 209 | L16: 1 | AD16: =sum(C16:AB16) -> 210
A17: 46119 | B17: 7 | C17: 210 | M17: 210 | AD17: =sum(C17:AB17) -> 420
A18: 46120 | B18: 8 | M18: 150 | AD18: =sum(C18:AB18) -> 150
A19: 46125 | B19: 10 | J19: 100 | L19: 300 | M19: 150 | AD19: =sum(C19:AB19) -> 550
A20: 46131 | B20: 13 | G20: 345 | J20: 181 | M20: 30 | P20: 309 | Q20: 300 | AD20: =sum(C20:AB20) -> 1165
A21: 46134 | B21: 14 | R21: 100 | T21: 300 | AD21: =sum(C21:AB21) -> 400
A22: 46139 | B22: 15 | N22: 200 | O22: 200 | R22: 100 | AD22: =sum(C22:AB22) -> 500
A23: 46148 | B23: 20 | J23: 14 | N23: 67 | O23: 132 | AD23: =sum(C23:AB23) -> 213
A24: 46148 | B24: 21 | R24: 120 | AD24: =sum(C24:AB24) -> 120
A25: 46149 | B25: 22 | E25: 180 | AD25: =sum(C25:AB25) -> 180
A26: 46150 | B26: 23 | E26: 120 | AD26: =sum(C26:AB26) -> 120
A27: 46153 | B27: 25 | M27: 418 | U27: 150 | AD27: =sum(C27:AB27) -> 568
A28: 46158 | B28: 29 | U28: 253 | V28: 300 | W28: 58 | AD28: =sum(C28:AB28) -> 611
A29: 46161 | B29: DKPT-30 | V29: 105 | AD29: =sum(C29:AB29) -> 105
A30: 46164 | B30: 33 | W30: 28 | X30: 156 | AD30: =sum(C30:AB30) -> 184
A31: 46165 | B31: 36 | W31: 100 | AD31: =sum(C31:AB31) -> 100
A32: 46168 | B32: 39 | W32: 509 | AD32: =sum(C32:AB32) -> 509
A33: 46171 | B33: 40 | W33: 50 | Y33: 150 | AD33: =sum(C33:AB33) -> 200
A34: 46173 | B34: 42 | M34: 390 | W34: 150 | Y34: 150 | AD34: =sum(C34:AB34) -> 690
A35: 46174 | B35: 44 | W35: 250 | AD35: =sum(C35:AB35) -> 250
A36: 46177 | B36: 45 | W36: 750 | AD36: =sum(C36:AB36) -> 750
A37: 46178 | B37: 46 | M37: 106 | W37: 505 | AD37: =sum(C37:AB37) -> 611
A38: 46181 | B38: 47 | E38: 250 | L38: 250 | P38: 317 | S38: 308 | W38: 100 | AD38: =sum(C38:AB38) -> 1225
A39: 46184 | B39: 48 | E39: 86 | L39: 67 | AD39: =sum(C39:AB39) -> 153
A40: 46185 | B40: 49 | V40: 195 | AD40: =sum(C40:AB40) -> 195
...

Sheet 1A1415
A1: ⬅ BACK TO REPORT | K1: =SUMIF(J9:J52,J1,K9:K52) -> 0
A2: Vendor Name | C2: ART & DESIGN | D2: Invoice Amount
A3: Place | C3: NOIDA | D3: In | E3: =SUM(D9:D100) -> 8
A4: Style / Po No.: | C4: 1D-1415 MUL SUIT | D4: Out | E4: =SUM(E9:E100) -> 8
A5: Invoice Date | D5: Bal Qty | E5: {=LOOKUP(9,1/(F:F<>""),F:F)} -> 0
A6: Invoice Number | D6: Unit | E6: PCS
H7: WORK ORDER NO. | K7: =SUM(K9:K102) -> 0
A8: Date | B8: Challan No. | C8: Size | D8: Inward Qty | E8: Outward Qty | F8: Balance | H8: Date | I8: Challan No. | J8: Item | K8: Qty | L8: Unit | M8: For
A9: 46198 | B9: JB-0429/26-27 | C9: =C4 -> 1D-1415 MUL SUIT | D9: 8 | F9: =D9-E9 -> 8
A10: 46212 | B10: 1879 | E10: 8 | F10: =IF(OR(D10<>"",E10<>""),F9+D10-E10,"") -> 0
F11: =IF(OR(D11<>"",E11<>""),F10+D11-E11,"")
F12: =IF(OR(D12<>"",E12<>""),F11+D12-E12,"")
F13: =IF(OR(D13<>"",E13<>""),F12+D13-E13,"")
F14: =IF(OR(D14<>"",E14<>""),F13+D14-E14,"")
F15: =IF(OR(D15<>"",E15<>""),F14+D15-E15,"")
F16: =IF(OR(D16<>"",E16<>""),F15+D16-E16,"")
F17: =IF(OR(D17<>"",E17<>""),F16+D17-E17,"")
F18: =IF(OR(D18<>"",E18<>""),F17+D18-E18,"")
F19: =IF(OR(D19<>"",E19<>""),F18+D19-E19,"")
F20: =IF(OR(D20<>"",E20<>""),F19+D20-E20,"")
F21: =IF(OR(D21<>"",E21<>""),F20+D21-E21,"")
F22: =IF(OR(D22<>"",E22<>""),F21+D22-E22,"")
... F52: =IF(OR(D52<>"",E52<>""),F51+D52-E52,"")

Sheet 1AD1549
A1: ⬅ BACK TO REPORT | K1: =SUMIF(J9:J52,J1,K9:K52) -> 0
A2: Vendor Name | C2: ART & DESIGN | D2: Invoice Amount
A3: Place | C3: NOIDA | D3: In | E3: =SUM(D9:D100) -> 25
A4: Style / Po No.: | C4: 1D-1549 M MUL SUIT | D4: Out | E4: =SUM(E9:E100) -> 25
A5: Invoice Date | D5: Bal Qty | E5: {=LOOKUP(9,1/(F:F<>""),F:F)} -> 0
A6: Invoice Number | D6: Unit | E6: PCS
H7: WORK ORDER NO. | K7: =SUM(K9:K102) -> 0
A8: Date | B8: Challan No. | C8: Size | D8: Inward Qty | E8: Outward Qty | F8: Balance | H8: Date | I8: Challan No. | J8: Item | K8: Qty | L8: Unit | M8: For
A9: 46198 | B9: JB-0429/26-27 | C9: =C4 -> 1D-1549 M MUL SUIT | D9: 25 | F9: =D9-E9 -> 25
A10: 46216 | B10: 1881 | E10: 25 | F10: =IF(OR(D10<>"",E10<>""),F9+D10-E10,"") -> 0
F11: =IF(OR(D11<>"",E11<>""),F10+D11-E11,"")
F12: =IF(OR(D12<>"",E12<>""),F11+D12-E12,"")
F13: =IF(OR(D13<>"",E13<>""),F12+D13-E13,"")
F14: =IF(OR(D14<>"",E14<>""),F13+D14-E14,"")
F15: =IF(OR(D15<>"",E15<>""),F14+D15-E15,"")
F16: =IF(OR(D16<>"",E16<>""),F15+D16-E16,"")
F17: =IF(OR(D17<>"",E17<>""),F16+D17-E17,"")
F18: =IF(OR(D18<>"",E18<>""),F17+D18-E18,"")
F19: =IF(OR(D19<>"",E19<>""),F18+D19-E19,"")
F20: =IF(OR(D20<>"",E20<>""),F19+D20-E20,"")
F21: =IF(OR(D21<>"",E21<>""),F20+D21-E21,"")
F22: =IF(OR(D22<>"",E22<>""),F21+D22-E22,"")
... F52: =IF(OR(D52<>"",E52<>""),F51+D52-E52,"")

Sheet 1AD1416
A1: ⬅ BACK TO REPORT | K1: =SUMIF(J9:J52,J1,K9:K52) -> 0
A2: Vendor Name | C2: ART & DESIGN | D2: Invoice Amount
A3: Place | C3: NOIDA | D3: In | E3: =SUM(D9:D100) -> 25
A4: Style / Po No.: | C4: 1D-1416 M MUL SUIT | D4: Out | E4: =SUM(E9:E100) -> 25
A5: Invoice Date | D5: Bal Qty | E5: {=LOOKUP(9,1/(F:F<>""),F:F)} -> 0
A6: Invoice Number | D6: Unit | E6: PCS
H7: WORK ORDER NO. | K7: =SUM(K9:K102) -> 0
A8: Date | B8: Challan No. | C8: Size | D8: Inward Qty | E8: Outward Qty | F8: Balance | H8: Date | I8: Challan No. | J8: Item | K8: Qty | L8: Unit | M8: For
A9: 46198 | B9: JB-0429/26-27 | C9: =C4 -> 1D-1416 M MUL SUIT | D9: 25 | F9: =D9-E9 -> 25
A10: 46212 | B10: 1879 | E10: 25 | F10: =IF(OR(D10<>"",E10<>""),F9+D10-E10,"") -> 0
F11: =IF(OR(D11<>"",E11<>""),F10+D11-E11,"")
F12: =IF(OR(D12<>"",E12<>""),F11+D12-E12,"")
F13: =IF(OR(D13<>"",E13<>""),F12+D13-E13,"")
F14: =IF(OR(D14<>"",E14<>""),F13+D14-E14,"")
F15: =IF(OR(D15<>"",E15<>""),F14+D15-E15,"")
F16: =IF(OR(D16<>"",E16<>""),F15+D16-E16,"")
F17: =IF(OR(D17<>"",E17<>""),F16+D17-E17,"")
F18: =IF(OR(D18<>"",E18<>""),F17+D18-E18,"")
F19: =IF(OR(D19<>"",E19<>""),F18+D19-E19,"")
F20: =IF(OR(D20<>"",E20<>""),F19+D20-E20,"")
F21: =IF(OR(D21<>"",E21<>""),F20+D21-E21,"")
F22: =IF(OR(D22<>"",E22<>""),F21+D22-E22,"")
... F52: =IF(OR(D52<>"",E52<>""),F51+D52-E52,"")

Sheet ART1438
A1: ⬅ BACK TO REPORT | K1: =SUMIF(J9:J52,J1,K9:K52) -> 0
A2: Vendor Name | C2: ART & DESIGN | D2: Invoice Amount
A3: Place | C3: NOIDA | D3: In | E3: =SUM(D9:D100) -> 38
A4: Style / Po No.: | C4: D-1438 M STOCK MUL SUIT | D4: Out | E4: =SUM(E9:E100) -> 38
A5: Invoice Date | D5: Bal Qty | E5: {=LOOKUP(9,1/(F:F<>""),F:F)} -> 0
A6: Invoice Number | D6: Unit | E6: PCS
H7: WORK ORDER NO. | K7: =SUM(K9:K102) -> 0
A8: Date | B8: Challan No. | C8: Size | D8: Inward Qty | E8: Outward Qty | F8: Balance | H8: Date | I8: Challan No. | J8: Item | K8: Qty | L8: Unit | M8: For
A9: 46195 | B9: JB-0410/26-27 | C9: =C4 -> D-1438 M STOCK MUL SUIT | D9: 38 | F9: =D9-E9 -> 38
A10: 46206 | B10: 1878 | E10: 38 | F10: =IF(OR(D10<>"",E10<>""),F9+D10-E10,"") -> 0
F11: =IF(OR(D11<>"",E11<>""),F10+D11-E11,"")
F12: =IF(OR(D12<>"",E12<>""),F11+D12-E12,"")
